Workbook

Sheet Projects_OLD
A1: Timestamp | B1: კონტრაგენტი : | C1: პროექტის დასახელება : | D1: შემოსავლის კოდი : | E1: თარიღი : | F1: თანხა : | G1: ვალუტა : | H1: პროექტის სტატუსი : | I1: თანამშრომელი : | J1: ORIS 1630 : | K1: კონტრაქტის # - | L1: პროექტი_GUID/ | M1: პროექტი// | N1: შემოსავლის კოდი_GUID | O1: კონტრაგენტი_GUID | P1: თანამშრომელი_GUID | Q1: [Collateral] | S1: Name1
A2: 44342.728 | B2: ოლიმპ ჯორჯია (ს.კ. 405231011) - შპს | C2: Biota Park | D2: 1.1.1. (+) შემოსავალი ლიფტების რეალიზაციიდან | E2: 43767 | F2: 350000 | G2: USD | H2: მიმდინარე | J2: 1 6 30 1270 | K2: 405231011/43767/1.1.1./1 | L2: 26A47FBE-6B71-4D89-B27B-4629DEEA1D34 | M2: Biota Park | 1.1.1. (+) შემოსავალი ლიფტების რეალიზაციიდან | ოლიმპ ჯორჯია (ს.კ. 405231011) - შპს | N2: B59170EC-16CC-499A-9FF7-0428DCB8F727 | O2: 6DECD64D-60DA-49AE-A9B3-49D7E02F2D62 | Q2: gio.nikabadze@gmail.com | S2: {=if(A2:A465<>"",left(M2:M465,iferror(search("(+)",M2:M465),search("(-)",M2:M465))-2)&" "&MID(M2:M465,SEARCH("|",M2:M465),1)&" "&left(B2:B465,SEARCH("(ს.კ.",B2:B465)-1)&" "&MID(M2:M465,SEARCH("|",M2:M465),1)&" "&TEXT(F2:F465,"#,##0.00")&" "&G2:G465&" "&MID(M2:M465,SEARCH("|",M2:M465),1)&" "&TEXT(E2:E465,"DD.MM.YYYY"),"")} -> Biota Park | 1.1.1. | ოლიმპ ჯორჯია | 350,000.00 USD | 29.10.2019
A3: 44342.729 | B3: ინდეკო (ს.კ. 202376133) - შპს | C3: Chakhrukhadze | D3: 1.1.1. (+) შემოსავალი ლიფტების რეალიზაციიდან | E3: 43762 | F3: 23100 | G3: USD | H3: მიმდინარე | J3: 1 6 30 541 4 | K3: 202376133/43762/1.1.1./1 | L3: BFCA9047-3C75-4EEB-9FE8-82617FFD3965 | M3: Chakhrukhadze | 1.1.1. (+) შემოსავალი ლიფტების რეალიზაციიდან | ინდეკო (ს.კ. 202376133) - შპს | N3: B59170EC-16CC-499A-9FF7-0428DCB8F727 | O3: 8E8E99BE-75FC-49EC-9D89-960E30E7CB06 | Q3: gio.nikabadze@gmail.com | S3: Chakhrukhadze | 1.1.1. | ინდეკო | 23,100.00 USD | 24.10.2019
A4: 44342.729 | B4: ბეტა ჯგუფი (ს.კ. 405171996) - შპს | C4: Med. University | D4: 1.1.1. (+) შემოსავალი ლიფტების რეალიზაციიდან | E4: 43767 | F4: 42500 | G4: USD | H4: მიმდინარე | K4: 405171996/43767/1.1.1./1 | L4: 00664103-FB2D-4EA7-A2B7-28064D745999 | M4: Med. University | 1.1.1. (+) შემოსავალი ლიფტების რეალიზაციიდან | ბეტა ჯგუფი (ს.კ. 405171996) - შპს | N4: B59170EC-16CC-499A-9FF7-0428DCB8F727 | O4: 3029E0C5-9337-4596-87DB-0A677D44A180 | Q4: gio.nikabadze@gmail.com | S4: Med. University | 1.1.1. | ბეტა ჯგუფი | 42,500.00 USD | 29.10.2019
A5: 44342.729 | B5: გიოკაპიტალი (ს.კ. 406155841) - შპს | C5: Varketili | D5: 1.1.1. (+) შემოსავალი ლიფტების რეალიზაციიდან | E5: 43724 | F5: 48500 | G5: USD | H5: მიმდინარე | J5: 1 6 30 1252 | K5: 406155841/43724/1.1.1./1 | L5: 80851DA9-84C4-4C2C-95FE-D6A0282F7B22 | M5: Varketili | 1.1.1. (+) შემოსავალი ლიფტების რეალიზაციიდან | გიოკაპიტალი (ს.კ. 406155841) - შპს | N5: B59170EC-16CC-499A-9FF7-0428DCB8F727 | O5: 97BEEA92-7829-4A09-8B1C-D0FE871340D4 | Q5: gio.nikabadze@gmail.com | S5: Varketili | 1.1.1. | გიოკაპიტალი | 48,500.00 USD | 16.09.2019
A6: 44342.729 | B6: რედ-კო (ს.კ. 405148415) - შპს | C6: Gudauri Redco Parking | D6: 1.1.1. (+) შემოსავალი ლიფტების რეალიზაციიდან | E6: 43734 | F6: 28000 | G6: USD | H6: მიმდინარე | K6: 405148415/43734/1.1.1./1 | L6: 2E1DDD27-332A-4E4A-B571-52B4DE3B8E04 | M6: Gudauri Redco Parking | 1.1.1. (+) შემოსავალი ლიფტების რეალიზაციიდან | რედ-კო (ს.კ. 405148415) - შპს | N6: B59170EC-16CC-499A-9FF7-0428DCB8F727 | O6: DA9D440B-CACD-4076-8B91-BFFCA46814B6 | Q6: gio.nikabadze@gmail.com | S6: Gudauri Redco Parking | 1.1.1. | რედ-კო | 28,000.00 USD | 26.09.2019
A7: 44342.729 | B7: მაია კვიჭიძე (ს.კ. 01008011243) - ფიზ. პირი | C7: Ortachala | D7: 1.1.1. (+) შემოსავალი ლიფტების რეალიზაციიდან | E7: 43672 | F7: 24000 | G7: USD | H7: მიმდინარე | K7: 01008011243/43672/1.1.1./1 | L7: 83FEC832-A4EA-4380-B5E9-85BEEECE8FA4 | M7: Ortachala | 1.1.1. (+) შემოსავალი ლიფტების რეალიზაციიდან | მაია კვიჭიძე (ს.კ. 01008011243) - ფიზ. პირი | N7: B59170EC-16CC-499A-9FF7-0428DCB8F727 | O7: D5136DB7-C17A-4DDB-9797-D1B10612D28C | Q7: gio.nikabadze@gmail.com | S7: Ortachala | 1.1.1. | მაია კვიჭიძე | 24,000.00 USD | 26.07.2019
A8: 44342.729 | B8: მოდუსი (ს.კ. 245565669) - შპს | C8: Modus Agladze | D8: 1.1.1. (+) შემოსავალი ლიფტების რეალიზაციიდან | E8: 43633 | F8: 57000 | G8: USD | H8: მიმდინარე | K8: 245565669/43633/1.1.1./1 | L8: ABDEF9CC-F0E1-4950-B30C-D46A8A8A912C | M8: Modus Agladze | 1.1.1. (+) შემოსავალი ლიფტების რეალიზაციიდან | მოდუსი (ს.კ. 245565669) - შპს | N8: B59170EC-16CC-499A-9FF7-0428DCB8F727 | O8: 9729C88B-F3C5-441A-8782-0656302A37F2 | Q8: gio.nikabadze@gmail.com | S8: Modus Agladze | 1.1.1. | მოდუსი | 57,000.00 USD | 17.06.2019
A9: 44342.729 | B9: ჰომბეი (ს.კ. 405255815) - შპს | C9: Crystal Bakuriani | D9: 1.1.1. (+) შემოსავალი ლიფტების რეალიზაციიდან | E9: 43608 | F9: 104500 | G9: USD | H9: მიმდინარე | K9: 405255815/43608/1.1.1./1 | L9: 230FCB1B-1310-4C49-9D2C-9CD5F9A792A3 | M9: Crystal Bakuriani | 1.1.1. (+) შემოსავალი ლიფტების რეალიზაციიდან | ჰომბეი (ს.კ. 405255815) - შპს | N9: B59170EC-16CC-499A-9FF7-0428DCB8F727 | O9: AAFC235A-2BBF-4CEC-A2AE-F1AEBABC12E4 | Q9: gio.nikabadze@gmail.com | S9: Crystal Bakuriani | 1.1.1. | ჰომბეი | 104,500.00 USD | 23.05.2019
A10: 44342.729 | B10: ანა აბუსერიძე (ს.კ. 61001051501) - ფიზ. პირი | C10: Abuseridze - Batumi | D10: 1.1.1. (+) შემოსავალი ლიფტების რეალიზაციიდან | E10: 43622 | F10: 31000 | G10: USD | H10: მიმდინარე | J10: 1 6 30 1179 | K10: 61001051501/43622/1.1.1./1 | L10: 4E89F135-A0AD-4622-97BD-7B68EF6062F8 | M10: Abuseridze - Batumi | 1.1.1. (+) შემოსავალი ლიფტების რეალიზაციიდან | ანა აბუსერიძე (ს.კ. 61001051501) - ფიზ. პირი | N10: B59170EC-16CC-499A-9FF7-0428DCB8F727 | O10: 15F35EBB-5A28-4C1B-B7CC-45FF3F31D4D6 | Q10: gio.nikabadze@gmail.com | S10: Abuseridze - Batumi | 1.1.1. | ანა აბუსერიძე | 31,000.00 USD | 06.06.2019
A11: 44342.729 | B11: იუნიქს ქონსთრაქშენ კომპანი (ს.კ. 405133822) - შპს | C11: UNIX Marselle | D11: 1.1.1. (+) შემოსავალი ლიფტების რეალიზაციიდან | E11: 43607 | F11: 340000 | G11: USD | H11: მიმდინარე | K11: 405133822/43607/1.1.1./1 | L11: CFFC1C06-B78B-45A0-8A02-37A23706EAFC | M11: UNIX Marselle | 1.1.1. (+) შემოსავალი ლიფტების რეალიზაციიდან | იუნიქს ქონსთრაქშენ კომპანი (ს.კ. 405133822) - შპს | N11: B59170EC-16CC-499A-9FF7-0428DCB8F727 | O11: B4968862-3843-414D-9E73-1A7611618B41 | Q11: gio.nikabadze@gmail.com | S11: UNIX Marselle | 1.1.1. | იუნიქს ქონსთრაქშენ კომპანი | 340,000.00 USD | 22.05.2019
A12: 44342.729 | B12: თბილისი პალასი (ს.კ. 405253381) - შპს | C12: Tbilisi Palace | D12: 1.1.1. (+) შემოსავალი ლიფტების რეალიზაციიდან | E12: 43460 | F12: 160000 | G12: USD | H12: მიმდინარე | K12: 405253381/43460/1.1.1./1 | L12: 125722B7-4DB0-4817-B1A4-DBA0B1B893D4 | M12: Tbilisi Palace | 1.1.1. (+) შემოსავალი ლიფტების რეალიზაციიდან | თბილისი პალასი (ს.კ. 405253381) - შპს | N12: B59170EC-16CC-499A-9FF7-0428DCB8F727 | O12: 3F5B4217-38D4-4FB8-B3F3-E856A10FFF06 | Q12: gio.nikabadze@gmail.com | S12: Tbilisi Palace | 1.1.1. | თბილისი პალასი | 160,000.00 USD | 26.12.2018
A13: 44342.729 | B13: თეგეტა მოტორსი (ს.კ. 202177205) - შპს | C13: Tegeta Batumi | D13: 1.1.1. (+) შემოსავალი ლიფტების რეალიზაციიდან | E13: 43479 | F13: 28650 | G13: USD | H13: მიმდინარე | K13: 202177205/43479/1.1.1./1 | L13: 255604D7-5424-4548-9CAA-ECFF960BB6AE | M13: Tegeta Batumi | 1.1.1. (+) შემოსავალი ლიფტების რეალიზაციიდან | თეგეტა მოტორსი (ს.კ. 202177205) - შპს | N13: B59170EC-16CC-499A-9FF7-0428DCB8F727 | O13: 5A21C207-4868-4EA6-9B48-5D0F743D5535 | Q13: gio.nikabadze@gmail.com | S13: Tegeta Batumi | 1.1.1. | თეგეტა მოტორსი | 28,650.00 USD | 14.01.2019
A14: 44342.729 | B14: Dar Building (ს.კ. 445420875) - შპს | C14: DAR TOWER | D14: 1.1.1. (+) შემოსავალი ლიფტების რეალიზაციიდან | E14: 43363 | F14: 1046340 | G14: USD | H14: მიმდინარე | J14: 1 6 30 853 1 | K14: 445420875/43363/1.1.1./1 | L14: A4EE54E2-C9BC-44F8-8554-44B9037B38D2 | M14: DAR TOWER | 1.1.1. (+) შემოსავალი ლიფტების რეალიზაციიდან | Dar Building (ს.კ. 445420875) - შპს | N14: B59170EC-16CC-499A-9FF7-0428DCB8F727 | O14: 7BF4A039-29BC-44AC-A87D-E8832394B94E | Q14: gio.nikabadze@gmail.com | S14: DAR TOWER | 1.1.1. | Dar Building | 1,046,340.00 USD | 20.09.2018
A15: 44342.729 | B15: ბათბილდინგი (ს.კ. 445509334) - შპს | C15: BAT Tower | D15: 1.1.1. (+) შემოსავალი ლიფტების რეალიზაციიდან | E15: 43461 | F15: 73000 | G15: USD | H15: მიმდინარე | J15: 1 6 30 1039 | K15: 445509334/43461/1.1.1./1 | L15: A7AFCD4C-CA26-464C-8F1B-E9A5240DCB0F | M15: BAT Tower | 1.1.1. (+) შემოსავალი ლიფტების რეალიზაციიდან | ბათბილდინგი (ს.კ. 445509334) - შპს | N15: B59170EC-16CC-499A-9FF7-0428DCB8F727 | O15: DAE7B000-963F-42D9-AA35-8F3F2F8A3716 | Q15: gio.nikabadze@gmail.com | S15: BAT Tower | 1.1.1. | ბათბილდინგი | 73,000.00 USD | 27.12.2018
A16: 44342.729 | B16: რუმი (ს.კ. 445481853) - შპს | C16: Rumi - batumi | D16: 1.1.1. (+) შემოსავალი ლიფტების რეალიზაციიდან | E16: 43816 | F16: 114550 | G16: USD | H16: მიმდინარე | J16: 1 6 30 1335 | K16: 445481853/43816/1.1.1./1 | L16: E95274D6-921C-43D1-B7C4-4F99A71C4005 | M16: Rumi - batumi | 1.1.1. (+) შემოსავალი ლიფტების რეალიზაციიდან | რუმი (ს.კ. 445481853) - შპს | N16: B59170EC-16CC-499A-9FF7-0428DCB8F727 | O16: BFABDF11-34C8-4815-A840-47DD5AAB9F4F | Q16: gio.nikabadze@gmail.com | S16: Rumi - batumi | 1.1.1. | რუმი | 114,550.00 USD | 17.12.2019
A17: 44342.729 | B17: ფალიაშვილის 63 (ს.კ. ICE000034) - ამხანაგობა | C17: Domus Paliashviliს 63 | D17: 1.1.1. (+) შემოსავალი ლიფტების რეალიზაციიდან | E17: 42948 | F17: 97000 | G17: GEL | H17: მიმდინარე | K17: ICE000034/42948/1.1.1./1 | L17: C897938C-00C4-4220-BAF1-CA29F3237D16 | M17: Domus Paliashviliს 63 | 1.1.1. (+) შემოსავალი ლიფტების რეალიზაციიდან | ფალიაშვილის 63 (ს.კ. ICE000034) - ამხანაგობა | N17: B59170EC-16CC-499A-9FF7-0428DCB8F727 | O17: 7F0A41E4-FA68-43E7-A979-126560D14B58 | Q17: gio.nikabadze@gmail.com | S17: Domus Paliashviliს 63 | 1.1.1. | ფალიაშვილის 63 | 97,000.00 GEL | 01.08.2017
A18: 44342.729 | B18: ეკომეტრი (ს.კ. 404464030) - შპს | C18: Gelovani 52 | D18: 1.1.1. (+) შემოსავალი ლიფტების რეალიზაციიდან | E18: 42923 | F18: 161000 | G18: USD | H18: მიმდინარე | K18: 404464030/42923/1.1.1./1 | L18: 196F7BB2-781C-4FF2-BAEE-C30045DA8E1E | M18: Gelovani 52 | 1.1.1. (+) შემოსავალი ლიფტების რეალიზაციიდან | ეკომეტრი (ს.კ. 404464030) - შპს | N18: B59170EC-16CC-499A-9FF7-0428DCB8F727 | O18: B25EF46E-8022-4949-A1EB-E8A1256C7A3B | Q18: gio.nikabadze@gmail.com | S18: Gelovani 52 | 1.1.1. | ეკომეტრი | 161,000.00 USD | 07.07.2017
A19: 44342.729 | B19: ჩემპიონი 2 (ს.კ. 248416432) - შპს | C19: Chempioni | D19: 1.1.1. (+) შემოსავალი ლიფტების რეალიზაციიდან | E19: 42536 | F19: 23924 | G19: USD | H19: მიმდინარე | K19: 248416432/42536/1.1.1./1 | L19: 42197EB0-C73A-4679-8D11-1DD3BAC96135 | M19: Chempioni | 1.1.1. (+) შემოსავალი ლიფტების რეალიზაციიდან | ჩემპიონი 2 (ს.კ. 248416432) - შპს | N19: B59170EC-16CC-499A-9FF7-0428DCB8F727 | O19: 967EE73E-8B77-4A8F-9FD3-AA36FF0ECB17 | Q19: gio.nikabadze@gmail.com | S19: Chempioni | 1.1.1. | ჩემპიონი 2 | 23,924.00 USD | 15.06.2016
A20: 44342.729 | B20: ნიუ თაიმ (ს.კ. 445440577) - შპს | C20: New Time | D20: 1.1.1. (+) შემოსავალი ლიფტების რეალიზაციიდან | E20: 42885 | F20: 150000 | G20: USD | H20: მიმდინარე | K20: 445440577/42885/1.1.1./1 | L20: 7A83BC1F-C807-436E-9390-775B1D423BFD | M20: New Time | 1.1.1. (+) შემოსავალი ლიფტების რეალიზაციიდან | ნიუ თაიმ (ს.კ. 445440577) - შპს | N20: B59170EC-16CC-499A-9FF7-0428DCB8F727 | O20: EEF69DEA-9E1B-41C3-B563-3922DCE0A9BD | Q20: gio.nikabadze@gmail.com | S20: New Time | 1.1.1. | ნიუ თაიმ | 150,000.00 USD | 30.05.2017
A21: 44342.729 | B21: ელტური-2008 (ს.კ. 248434038) - შპს | C21: Green Cape | D21: 1.1.1. (+) შემოსავალი ლიფტების რეალიზაციიდან | E21: 43460 | F21: 70360 | G21: USD | H21: მიმდინარე | K21: 248434038/43460/1.1.1./1 | L21: D9285AF5-11A4-4764-B11B-745E9DAF1D34 | M21: Green Cape | 1.1.1. (+) შემოსავალი ლიფტების რეალიზაციიდან | ელტური-2008 (ს.კ. 248434038) - შპს | N21: B59170EC-16CC-499A-9FF7-0428DCB8F727 | O21: 0A7F5182-3B4F-4292-8569-FC31854BA5B4 | Q21: gio.nikabadze@gmail.com | S21: Green Cape | 1.1.1. | ელტური-2008 | 70,360.00 USD | 26.12.2018
A22: 44342.729 | B22: ინდეკო (ს.კ. 202376133) - შპს | C22: Indeko - shartava 39 | D22: 1.1.1. (+) შემოსავალი ლიფტების რეალიზაციიდან | E22: 43460 | F22: 155520 | G22: USD | H22: მიმდინარე | K22: 202376133/42345/1.1.1./1 | L22: C5E1547A-8529-495B-974D-92544D0F1C66 | M22: Indeko - shartava 39 | 1.1.1. (+) შემოსავალი ლიფტების რეალიზაციიდან | ინდეკო (ს.კ. 202376133) - შპს | N22: B59170EC-16CC-499A-9FF7-0428DCB8F727 | O22: 8E8E99BE-75FC-49EC-9D89-960E30E7CB06 | Q22: gio.nikabadze@gmail.com | S22: Indeko - shartava 39 | 1.1.1. | ინდეკო | 155,520.00 USD | 26.12.2018
A23: 44342.729 | B23: რედ-კო (ს.კ. 405148415) - შპს | C23: Redco 1 | D23: 1.1.1. (+) შემოსავალი ლიფტების რეალიზაციიდან | E23: 43248 | F23: 370000 | G23: USD | H23: მიმდინარე | J23: 1 6 30 917 2 | K23: 405148415/43248/1.1.1./1 | L23: D421D947-C097-4870-8EF1-C7F724377248 | M23: Redco 1 | 1.1.1. (+) შემოსავალი ლიფტების რეალიზაციიდან | რედ-კო (ს.კ. 405148415) - შპს | N23: B59170EC-16CC-499A-9FF7-0428DCB8F727 | O23: DA9D440B-CACD-4076-8B91-BFFCA46814B6 | Q23: gio.nikabadze@gmail.com | S23: Redco 1 | 1.1.1. | რედ-კო | 370,000.00 USD | 28.05.2018
A24: 44342.729 | B24: ბიზნეს ცენტრი დელისი (ს.კ. 204854014) - სს | C24: Delisi | D24: 1.1.1. (+) შემოსავალი ლიფტების რეალიზაციიდან | E24: 42598 | F24: 53454 | G24: USD | H24: მიმდინარე | K24: 204854014/42598/1.1.1./1 | L24: 2496A0E0-1118-49DC-8A82-539003DC1B23 | M24: Delisi | 1.1.1. (+) შემოსავალი ლიფტების რეალიზაციიდან | ბიზნეს ცენტრი დელისი (ს.კ. 204854014) - სს | N24: B59170EC-16CC-499A-9FF7-0428DCB8F727 | O24: 62F6C15C-8FCC-4A60-B37E-8A3DE9D20A48 | Q24: gio.nikabadze@gmail.com | S24: Delisi | 1.1.1. | ბიზნეს ცენტრი დელისი | 53,454.00 USD | 16.08.2016
A25: 44342.729 | B25: შველა (ს.კ. 448396021) - შპს | C25: Shvela | D25: 1.1.1. (+) შემოსავალი ლიფტების რეალიზაციიდან | E25: 42536 | F25: 50206 | G25: USD | H25: მიმდინარე | K25: 448396021/42536/1.1.1./1 | L25: 1C2CAB23-3967-41F9-AC61-62415AE0373C | M25: Shvela | 1.1.1. (+) შემოსავალი ლიფტების რეალიზაციიდან | შველა (ს.კ. 448396021) - შპს | N25: B59170EC-16CC-499A-9FF7-0428DCB8F727 | O25: A5C44F5D-1F9C-4BC1-BD39-C8B2E88BC49A | Q25: gio.nikabadze@gmail.com | S25: Shvela | 1.1.1. | შველა | 50,206.00 USD | 15.06.2016
A26: 44342.729 | B26: ბკ კაპიტალი (ს.კ. 205057123) - შპს | C26: Moxy Zaabruken Hotel 1 | D26: 1.1.1. (+) შემოსავალი ლიფტების რეალიზაციიდან | E26: 42647 | F26: 157608.67 | G26: USD | H26: მიმდინარე | K26: 205057123/42647/1.1.1./1 | L26: 202843CA-C5C3-4057-8040-234B6C369B5E | M26: Moxy Zaabruken Hotel | 1.1.1. (+) შემოსავალი ლიფტების რეალიზაციიდან | ბკ კაპიტალი (ს.კ. 205057123) - შპს | N26: B59170EC-16CC-499A-9FF7-0428DCB8F727 | O26: D57E2878-F57C-4B96-B89E-A8B81F35634A | Q26: gio.nikabadze@gmail.com | S26: Moxy Zaabruken Hotel | 1.1.1. | ბკ კაპიტალი | 157,608.67 USD | 04.10.2016
A27: 44342.729 | B27: ინჟინერთა ჯგუფი (ს.კ. 400101457) - შპს | C27: Tbilisi Gardens | D27: 1.1.1. (+) შემოსავალი ლიფტების რეალიზაციიდან | E27: 42723 | F27: 325000 | G27: USD | H27: მიმდინარე | K27: 400101457/42723/1.1.1./1 | L27: 8C8C52A5-1A7C-485F-9AC8-043862EF3D55 | M27: Tbilisi Gardens | 1.1.1. (+) შემოსავალი ლიფტების რეალიზაციიდან | ინჟინერთა ჯგუფი (ს.კ. 400101457) - შპს | N27: B59170EC-16CC-499A-9FF7-0428DCB8F727 | O27: 2ED6F730-5337-4222-94F9-284E801BCE61 | Q27: gio.nikabadze@gmail.com | S27: Tbilisi Gardens | 1.1.1. | ინჟინერთა ჯგუფი | 325,000.00 USD | 19.12.2016
A28: 44342.729 | B28: მოდუსი (ს.კ. 245565669) - შპს | C28: Modus Kakhety HW | D28: 1.1.1. (+) შემოსავალი ლიფტების რეალიზაციიდან | E28: 42641 | F28: 25000 | G28: USD | H28: მიმდინარე | K28: 245565669/42641/1.1.1./1 | L28: BFD4409A-7F01-4C7C-9F40-73A80C2E63A6 | M28: Modus Kakhety HW | 1.1.1. (+) შემოსავალი ლიფტების რეალიზაციიდან | მოდუსი (ს.კ. 245565669) - შპს | N28: B59170EC-16CC-499A-9FF7-0428DCB8F727 | O28: 9729C88B-F3C5-441A-8782-0656302A37F2 | Q28: gio.nikabadze@gmail.com | S28: Modus Kakhety HW | 1.1.1. | მოდუსი | 25,000.00 USD | 28.09.2016
A29: 44342.729 | B29: სითი დეველოპმენტ (ს.კ. 404481324) - შპს | C29: Kbuleti Str. - Khomeriki | D29: 1.1.1. (+) შემოსავალი ლიფტების რეალიზაციიდან | E29: 42485 | F29: 36577 | G29: USD | H29: მიმდინარე | K29: 404481324/42485/1.1.1./1 | L29: A53105CE-1BDB-4625-B775-A01DA1F6C8AD | M29: Kbuleti Str. - Khomeriki | 1.1.1. (+) შემოსავალი ლიფტების რეალიზაციიდან | სითი დეველოპმენტ (ს.კ. 404481324) - შპს | N29: B59170EC-16CC-499A-9FF7-0428DCB8F727 | O29: 57A60218-744B-4922-BF21-F9C52A01DAF6 | Q29: gio.nikabadze@gmail.com | S29: Kbuleti Str. - Khomeriki | 1.1.1. | სითი დეველოპმენტ | 36,577.00 USD | 25.04.2016
A30: 44342.729 | B30: დომუს დეველოპმენტ (ს.კ. 205210261) - შპს | C30: Domus | D30: 1.1.1. (+) შემოსავალი ლიფტების რეალიზაციიდან | E30: 42355 | F30: 527700 | G30: USD | H30: მიმდინარე | K30: 205210261/42355/1.1.1./1 | L30: F154242F-E028-49D8-B7BE-42EB31281CD5 | M30: Domus | 1.1.1. (+) შემოსავალი ლიფტების რეალიზაციიდან | დომუს დეველოპმენტ (ს.კ. 205210261) - შპს | N30: B59170EC-16CC-499A-9FF7-0428DCB8F727 | O30: A3C5943B-D1C3-4CB2-946C-86BF678B6183 | Q30: gio.nikabadze@gmail.com | S30: Domus | 1.1.1. | დომუს დეველოპმენტ | 527,700.00 USD | 17.12.2015
A31: 44342.729 | B31: ირაკლი კაციტაძე (ს.კ. 01008004604) - ფიზ. პირი | C31: Paliashvili 23 | D31: 1.1.2. (+) შემოსავალი ლიფტების სერვისიდან - გეგმიური | E31: 43831 | F31: 1 | G31: GEL | H31: მიმდინარე | K31: 01008004604/43831/1.1.2./1 | L31: 6D999F5B-2199-4578-A47D-FDC2DF179273 | M31: Paliashvili 23 | 1.1.2. (+) შემოსავალი ლიფტების სერვისიდან - გეგმიური | ირაკლი კაციტაძე (ს.კ. 01008004604) - ფიზ. პირი | N31: 12238130-9D12-4099-A48B-9EB5A085E0F8 | O31: 9AE0C821-91FF-44A4-90E6-F71F98BC044C | Q31: gio.nikabadze@gmail.com | S31: Paliashvili 23 | 1.1.2. | ირაკლი კაციტაძე | 1.00 GEL | 01.01.2020
A32: 44342.729 | B32: ბკ კაპიტალი (ს.კ. 205057123) - შპს | C32: Moxy Zabruken Restaurant | D32: 1.1.1. (+) შემოსავალი ლიფტების რეალიზაციიდან | E32: 43742 | F32: 78804.33 | G32: USD | H32: მიმდინარე | K32: 205057123/43742/1.1.1./1 | L32: 5E543EA8-4A6A-4F8C-9F72-071B61F85EEB | M32: Moxy Zabruken Restaurant | 1.1.1. (+) შემოსავალი ლიფტების რეალიზაციიდან | ბკ კაპიტალი (ს.კ. 205057123) - შპს | N32: B59170EC-16CC-499A-9FF7-0428DCB8F727 | O32: D57E2878-F57C-4B96-B89E-A8B81F35634A | Q32: gio.nikabadze@gmail.com | S32: Moxy Zabruken Restaurant | 1.1.1. | ბკ კაპიტალი | 78,804.33 USD | 04.10.2019
A33: 44342.729 | B33: ორბი ჯგუფი ბათუმი (ს.კ. 445468798) - შპს | C33: TWIN TOWER | D33: 1.1.1. (+) შემოსავალი ლიფტების რეალიზაციიდან | E33: 43059 | F33: 3273908 | G33: USD | H33: მიმდინარე | J33: 1 6 30 773 1 | K33: 445468798/43059/1.1.1./1 | L33: C35D9FF1-3A09-4634-9BFA-87C709266063 | M33: TWIN TOWER | 1.1.1. (+) შემოსავალი ლიფტების რეალიზაციიდან | ორბი ჯგუფი ბათუმი (ს.კ. 445468798) - შპს | N33: B59170EC-16CC-499A-9FF7-0428DCB8F727 | O33: E284E0FD-A2B7-4D93-8E91-006FF0A8A4CE | Q33: gio.nikabadze@gmail.com | S33: TWIN TOWER | 1.1.1. | ორბი ჯგუფი ბათუმი | 3,273,908.00 USD | 20.11.2017
A34: 44342.729 | B34: აი ჯი დეველოფმენტ ჯორჯია (ს.კ. 404851503) - შპს | C34: City Mall | D34: 1.1.1. (+) შემოსავალი ლიფტების რეალიზაციიდან | E34: 43354 | F34: 1194345 | G34: USD | H34: მიმდინარე | J34: 1 6 30 971 | K34: 404851503/43354/1.1.1./1 | L34: EA15EDA6-F906-4932-87BA-DDB8898D4EBC | M34: City Mall | 1.1.1. (+) შემოსავალი ლიფტების რეალიზაციიდან | აი ჯი დეველოფმენტ ჯორჯია (ს.კ. 404851503) - შპს | N34: B59170EC-16CC-499A-9FF7-0428DCB8F727 | O34: DDFBBDF4-5DA2-4BD2-918A-77AAF121BF72 | Q34: gio.nikabadze@gmail.com | S34: City Mall | 1.1.1. | აი ჯი დეველოფმენტ ჯორჯია | 1,194,345.00 USD | 11.09.2018
A35: 44342.729 | B35: რენთინგ ბიენბი (ს.კ. 404564244) - სს | C35: Renting BNB | D35: 1.1.1. (+) შემოსავალი ლიფტების რეალიზაციიდან | E35: 43886 | F35: 26000 | G35: USD | H35: მიმდინარე | J35: 1 6 30 1429 | K35: 404564244/43886/1.1.1./1 | L35: 55F53FA9-CDDE-4FBA-91A1-FEAFA51B29A0 | M35: Renting BNB | 1.1.1. (+) შემოსავალი ლიფტების რეალიზაციიდან | რენთინგ ბიენბი (ს.კ. 404564244) - სს | N35: B59170EC-16CC-499A-9FF7-0428DCB8F727 | O35: 9B349A17-7CE1-4232-98C6-02C565C3642C | Q35: gio.nikabadze@gmail.com | S35: Renting BNB | 1.1.1. | რენთინგ ბიენბი | 26,000.00 USD | 25.02.2020
A36: 44342.729 | B36: ტრანსმშენი (ს.კ. 212274812) - სს | C36: Aeroporti | D36: 1.1.1. (+) შემოსავალი ლიფტების რეალიზაციიდან | E36: 43699 | F36: 20000 | G36: USD | H36: მიმდინარე | K36: 212274812/43699/1.1.1./1 | L36: 44F2F4A0-908E-42D1-B73F-04859CACCB08 | M36: Aeroporti | 1.1.1. (+) შემოსავალი ლიფტების რეალიზაციიდან | ტრანსმშენი (ს.კ. 212274812) - სს | N36: B59170EC-16CC-499A-9FF7-0428DCB8F727 | O36: 9B21D54A-56D8-405D-95E2-A05872C7C1E9 | Q36: gio.nikabadze@gmail.com | S36: Aeroporti | 1.1.1. | ტრანსმშენი | 20,000.00 USD | 22.08.2019
A37: 44342.729 | B37: ბეტა ჯგუფი (ს.კ. 405171996) - შპს | C37: Dividers Med Uni | D37: 1.1.1. (+) შემოსავალი ლიფტების რეალიზაციიდან | E37: 43477 | F37: 11000 | G37: GEL | H37: მიმდინარე | K37: 405171996/43477/1.1.1./1 | L37: 2F958FC8-AC98-416D-BEAC-E4C6006FCCB3 | M37: Dividers Med Uni | 1.1.1. (+) შემოსავალი ლიფტების რეალიზაციიდან | ბეტა ჯგუფი (ს.კ. 405171996) - შპს | N37: B59170EC-16CC-499A-9FF7-0428DCB8F727 | O37: 3029E0C5-9337-4596-87DB-0A677D44A180 | Q37: gio.nikabadze@gmail.com | S37: Dividers Med Uni | 1.1.1. | ბეტა ჯგუფი | 11,000.00 GEL | 12.01.2019
A38: 44342.729 | B38: ლუდსახარში ორი კათხა (ს.კ. 406283338) - შპს | C38: Brewery 1 (300KG) | D38: 1.1.1. (+) შემოსავალი ლიფტების რეალიზაციიდან | E38: 43896 | F38: 10610 | G38: USD | H38: მიმდინარე | K38: 406283338/43896/1.1.1./1 | L38: 4DB7E760-9ECD-4426-BB50-E293E58D2B02 | M38: Brewery 1 (300KG) | 1.1.1. (+) შემოსავალი ლიფტების რეალიზაციიდან | ლუდსახარში ორი კათხა (ს.კ. 406283338) - შპს | N38: B59170EC-16CC-499A-9FF7-0428DCB8F727 | O38: 1C2A10A9-FA2F-437B-8C70-F109D1C009EE | Q38: gio.nikabadze@gmail.com | S38: Brewery 1 (300KG) | 1.1.1. | ლუდსახარში ორი კათხა | 10,610.00 USD | 06.03.2020
A39: 44342.729 | B39: ახალშენი 2016 (ს.კ. 405136758) - შპს | C39: Khiliani | D39: 1.1.1. (+) შემოსავალი ლიფტების რეალიზაციიდან | E39: 43677 | F39: 26400 | G39: USD | H39: მიმდინარე | K39: 405136758/43677/1.1.1./1 | L39: E136ACFA-DBED-49EE-B224-24513754542C | M39: Khiliani | 1.1.1. (+) შემოსავალი ლიფტების რეალიზაციიდან | ახალშენი 2016 (ს.კ. 405136758) - შპს | N39: B59170EC-16CC-499A-9FF7-0428DCB8F727 | O39: 04FB28EA-5501-4B01-BA1D-C2955C0E1213 | Q39: gio.nikabadze@gmail.com | S39: Khiliani | 1.1.1. | ახალშენი 2016 | 26,400.00 USD | 31.07.2019
A40: 44342.729 | B40: ორბი ჯგუფი ბათუმი (ს.კ. 445468798) - შპს | C40: ORBI Office Lift | D40: 1.1.1. (+) შემოსავალი ლიფტების რეალიზაციიდან | E40: 43788 | F40: 30000 | G40: USD | H40: მიმდინარე | K40: 445468798/43788/1.1.1./1 | L40: 5B0BA252-1105-4374-8654-430AE04E8A64 | M40: ORBI Office Lift | 1.1.1. (+) შემოსავალი ლიფტების რეალიზაციიდან | ორბი ჯგუფი ბათუმი (ს.კ. 445468798) - შპს | N40: B59170EC-16CC-499A-9FF7-0428DCB8F727 | O40: E284E0FD-A2B7-4D93-8E91-006FF0A8A4CE | Q40: gio.nikabadze@gmail.com | S40: ORBI Office Lift | 1.1.1. | ორბი ჯგუფი ბათუმი | 30,000.00 USD | 19.11.2019
...

Sheet Old Info
A1: Timestamp | B1: კონტრაგენტი : | C1: პროექტის დასახელება : | D1: შემოსავლის კოდი : | E1: თარიღი : | F1: თანხა : | G1: ვალუტა : | H1: პროექტის სტატუსი : | I1: თანამშრომელი : | J1: ORIS 1630 : | K1: კონტრაქტის # - | L1: პროექტი_GUID/ | M1: პროექტი// | N1: შემოსავლის კოდი_GUID | O1: კონტრაგენტი_GUID | P1: თანამშრომელი_GUID | Q1: Collateral
A2: 44182.055 | B2: ოლიმპ ჯორჯია (ს.კ. 405231011) - შპს | C2: Biota Park | D2: 1.1.1. (+) შემოსავალი ლიფტების რეალიზაციიდან | E2: 43767 | F2: 350000 | G2: USD | H2: მიმდინარე | J2: 1 6 30 1270 | K2: 405231011/43767/1.1.1./1 | L2: 26A47FBE-6B71-4D89-B27B-4629DEEA1D34 | M2: Biota Park | 1.1.1. (+) შემოსავალი ლიფტების რეალიზაციიდან | ოლიმპ ჯორჯია (ს.კ. 405231011) - შპს | N2: B59170EC-16CC-499A-9FF7-0428DCB8F727 | O2: 6DECD64D-60DA-49AE-A9B3-49D7E02F2D62 | Q2: gio.nikabadze@gmail.com | T2: კონტრაგენტი :
A3: 44182.055 | B3: ინდეკო (ს.კ. 202376133) - შპს | C3: Chakhrukhadze | D3: 1.1.1. (+) შემოსავალი ლიფტების რეალიზაციიდან | E3: 43762 | F3: 23100 | G3: USD | H3: მიმდინარე | J3: 1 6 30 541 4 | K3: 202376133/43762/1.1.1./1 | L3: BFCA9047-3C75-4EEB-9FE8-82617FFD3965 | M3: Chakhrukhadze | 1.1.1. (+) შემოსავალი ლიფტების რეალიზაციიდან | ინდეკო (ს.კ. 202376133) - შპს | N3: B59170EC-16CC-499A-9FF7-0428DCB8F727 | O3: 8E8E99BE-75FC-49EC-9D89-960E30E7CB06 | Q3: gio.nikabadze@gmail.com | T3: პროექტის დასახელება :
A4: 44182.055 | B4: ბეტა ჯგუფი (ს.კ. 405171996) - შპს | C4: Med. University | D4: 1.1.1. (+) შემოსავალი ლიფტების რეალიზაციიდან | E4: 43767 | F4: 42500 | G4: USD | H4: მიმდინარე | K4: 405171996/43767/1.1.1./1 | L4: 00664103-FB2D-4EA7-A2B7-28064D745999 | M4: Med. University | 1.1.1. (+) შემოსავალი ლიფტების რეალიზაციიდან | ბეტა ჯგუფი (ს.კ. 405171996) - შპს | N4: B59170EC-16CC-499A-9FF7-0428DCB8F727 | O4: 3029E0C5-9337-4596-87DB-0A677D44A180 | Q4: gio.nikabadze@gmail.com | T4: შემოსავლის კოდი :
A5: 44182.055 | B5: გიოკაპიტალი (ს.კ. 406155841) - შპს | C5: Varketili | D5: 1.1.1. (+) შემოსავალი ლიფტების რეალიზაციიდან | E5: 43724 | F5: 48500 | G5: USD | H5: მიმდინარე | J5: 1 6 30 1252 | K5: 406155841/43724/1.1.1./1 | L5: 80851DA9-84C4-4C2C-95FE-D6A0282F7B22 | M5: Varketili | 1.1.1. (+) შემოსავალი ლიფტების რეალიზაციიდან | გიოკაპიტალი (ს.კ. 406155841) - შპს | N5: B59170EC-16CC-499A-9FF7-0428DCB8F727 | O5: 97BEEA92-7829-4A09-8B1C-D0FE871340D4 | Q5: gio.nikabadze@gmail.com | T5: თარიღი :
A6: 44182.055 | B6: რედ-კო (ს.კ. 405148415) - შპს | C6: Gudauri Redco Parking | D6: 1.1.1. (+) შემოსავალი ლიფტების რეალიზაციიდან | E6: 43734 | F6: 28000 | G6: USD | H6: მიმდინარე | K6: 405148415/43734/1.1.1./1 | L6: 2E1DDD27-332A-4E4A-B571-52B4DE3B8E04 | M6: Gudauri Redco Parking | 1.1.1. (+) შემოსავალი ლიფტების რეალიზაციიდან | რედ-კო (ს.კ. 405148415) - შპს | N6: B59170EC-16CC-499A-9FF7-0428DCB8F727 | O6: DA9D440B-CACD-4076-8B91-BFFCA46814B6 | Q6: gio.nikabadze@gmail.com | T6: თანხა :
A7: 44182.055 | B7: მაია კვიჭიძე (ს.კ. 01008011243) - ფიზ. პირი | C7: Ortachala | D7: 1.1.1. (+) შემოსავალი ლიფტების რეალიზაციიდან | E7: 43672 | F7: 24000 | G7: USD | H7: მიმდინარე | K7: 01008011243/43672/1.1.1./1 | L7: 83FEC832-A4EA-4380-B5E9-85BEEECE8FA4 | M7: Ortachala | 1.1.1. (+) შემოსავალი ლიფტების რეალიზაციიდან | მაია კვიჭიძე (ს.კ. 01008011243) - ფიზ. პირი | N7: B59170EC-16CC-499A-9FF7-0428DCB8F727 | O7: D5136DB7-C17A-4DDB-9797-D1B10612D28C | Q7: gio.nikabadze@gmail.com | T7: ვალუტა :
A8: 44182.056 | B8: მოდუსი (ს.კ. 245565669) - შპს | C8: Modus Agladze | D8: 1.1.1. (+) შემოსავალი ლიფტების რეალიზაციიდან | E8: 43633 | F8: 57000 | G8: USD | H8: მიმდინარე | K8: 245565669/43633/1.1.1./1 | L8: ABDEF9CC-F0E1-4950-B30C-D46A8A8A912C | M8: Modus Agladze | 1.1.1. (+) შემოსავალი ლიფტების რეალიზაციიდან | მოდუსი (ს.კ. 245565669) - შპს | N8: B59170EC-16CC-499A-9FF7-0428DCB8F727 | O8: 9729C88B-F3C5-441A-8782-0656302A37F2 | Q8: gio.nikabadze@gmail.com | T8: პროექტის სტატუსი : | W8: 1
A9: 44182.056 | B9: ჰომბეი (ს.კ. 405255815) - შპს | C9: Crystal Bakuriani | D9: 1.1.1. (+) შემოსავალი ლიფტების რეალიზაციიდან | E9: 43608 | F9: 104500 | G9: USD | H9: მიმდინარე | K9: 405255815/43608/1.1.1./1 | L9: 230FCB1B-1310-4C49-9D2C-9CD5F9A792A3 | M9: Crystal Bakuriani | 1.1.1. (+) შემოსავალი ლიფტების რეალიზაციიდან | ჰომბეი (ს.კ. 405255815) - შპს | N9: B59170EC-16CC-499A-9FF7-0428DCB8F727 | O9: AAFC235A-2BBF-4CEC-A2AE-F1AEBABC12E4 | Q9: gio.nikabadze@gmail.com | T9: თანამშრომელი : | W9: 1 | X9: 0
A10: 44182.056 | B10: ანა აბუსერიძე (ს.კ. 61001051501) - ფიზ. პირი | C10: Abuseridze - Batumi | D10: 1.1.1. (+) შემოსავალი ლიფტების რეალიზაციიდან | E10: 43622 | F10: 31000 | G10: USD | H10: მიმდინარე | J10: 1 6 30 1179 | K10: 61001051501/43622/1.1.1./1 | L10: 4E89F135-A0AD-4622-97BD-7B68EF6062F8 | M10: Abuseridze - Batumi | 1.1.1. (+) შემოსავალი ლიფტების რეალიზაციიდან | ანა აბუსერიძე (ს.კ. 61001051501) - ფიზ. პირი | N10: B59170EC-16CC-499A-9FF7-0428DCB8F727 | O10: 15F35EBB-5A28-4C1B-B7CC-45FF3F31D4D6 | Q10: gio.nikabadze@gmail.com | T10: ORIS 1630 :
A11: 44182.056 | B11: იუნიქს ქონსთრაქშენ კომპანი (ს.კ. 405133822) - შპს | C11: UNIX Marselle | D11: 1.1.1. (+) შემოსავალი ლიფტების რეალიზაციიდან | E11: 43607 | F11: 340000 | G11: USD | H11: მიმდინარე | K11: 405133822/43607/1.1.1./1 | L11: CFFC1C06-B78B-45A0-8A02-37A23706EAFC | M11: UNIX Marselle | 1.1.1. (+) შემოსავალი ლიფტების რეალიზაციიდან | იუნიქს ქონსთრაქშენ კომპანი (ს.კ. 405133822) - შპს | N11: B59170EC-16CC-499A-9FF7-0428DCB8F727 | O11: B4968862-3843-414D-9E73-1A7611618B41 | Q11: gio.nikabadze@gmail.com | T11: კონტრაქტის # -
A12: 44182.056 | B12: თბილისი პალასი (ს.კ. 405253381) - შპს | C12: Tbilisi Palace | D12: 1.1.1. (+) შემოსავალი ლიფტების რეალიზაციიდან | E12: 43460 | F12: 160000 | G12: USD | H12: მიმდინარე | K12: 405253381/43460/1.1.1./1 | L12: 125722B7-4DB0-4817-B1A4-DBA0B1B893D4 | M12: Tbilisi Palace | 1.1.1. (+) შემოსავალი ლიფტების რეალიზაციიდან | თბილისი პალასი (ს.კ. 405253381) - შპს | N12: B59170EC-16CC-499A-9FF7-0428DCB8F727 | O12: 3F5B4217-38D4-4FB8-B3F3-E856A10FFF06 | Q12: gio.nikabadze@gmail.com | T12: პროექტი_GUID/
A13: 44182.056 | B13: თეგეტა მოტორსი (ს.კ. 202177205) - შპს | C13: Tegeta Batumi | D13: 1.1.1. (+) შემოსავალი ლიფტების რეალიზაციიდან | E13: 43479 | F13: 28650 | G13: USD | H13: მიმდინარე | K13: 202177205/43479/1.1.1./1 | L13: 255604D7-5424-4548-9CAA-ECFF960BB6AE | M13: Tegeta Batumi | 1.1.1. (+) შემოსავალი ლიფტების რეალიზაციიდან | თეგეტა მოტორსი (ს.კ. 202177205) - შპს | N13: B59170EC-16CC-499A-9FF7-0428DCB8F727 | O13: 5A21C207-4868-4EA6-9B48-5D0F743D5535 | Q13: gio.nikabadze@gmail.com | T13: პროექტი//
A14: 44182.056 | B14: Dar Building (ს.კ. 445420875) - შპს | C14: DAR TOWER | D14: 1.1.1. (+) შემოსავალი ლიფტების რეალიზაციიდან | E14: 43363 | F14: 1046340 | G14: USD | H14: მიმდინარე | J14: 1 6 30 853 1 | K14: 445420875/43363/1.1.1./1 | L14: A4EE54E2-C9BC-44F8-8554-44B9037B38D2 | M14: DAR TOWER | 1.1.1. (+) შემოსავალი ლიფტების რეალიზაციიდან | Dar Building (ს.კ. 445420875) - შპს | N14: B59170EC-16CC-499A-9FF7-0428DCB8F727 | O14: 7BF4A039-29BC-44AC-A87D-E8832394B94E | Q14: gio.nikabadze@gmail.com | T14: შემოსავლის კოდი_GUID | W14: =38317.6666666666/365 -> 104.97991
A15: 44182.056 | B15: ბათბილდინგი (ს.კ. 445509334) - შპს | C15: BAT Tower | D15: 1.1.1. (+) შემოსავალი ლიფტების რეალიზაციიდან | E15: 43461 | F15: 73000 | G15: USD | H15: მიმდინარე | K15: 445509334/43461/1.1.1./1 | L15: A7AFCD4C-CA26-464C-8F1B-E9A5240DCB0F | M15: BAT Tower | 1.1.1. (+) შემოსავალი ლიფტების რეალიზაციიდან | ბათბილდინგი (ს.კ. 445509334) - შპს | N15: B59170EC-16CC-499A-9FF7-0428DCB8F727 | O15: DAE7B000-963F-42D9-AA35-8F3F2F8A3716 | Q15: gio.nikabadze@gmail.com | T15: კონტრაგენტი_GUID
A16: 44182.056 | B16: რუმი (ს.კ. 445481853) - შპს | C16: Rumi - batumi | D16: 1.1.1. (+) შემოსავალი ლიფტების რეალიზაციიდან | E16: 43816 | F16: 114550 | G16: USD | H16: მიმდინარე | J16: 1 6 30 1335 | K16: 445481853/43816/1.1.1./1 | L16: E95274D6-921C-43D1-B7C4-4F99A71C4005 | M16: Rumi - batumi | 1.1.1. (+) შემოსავალი ლიფტების რეალიზაციიდან | რუმი (ს.კ. 445481853) - შპს | N16: B59170EC-16CC-499A-9FF7-0428DCB8F727 | O16: BFABDF11-34C8-4815-A840-47DD5AAB9F4F | Q16: gio.nikabadze@gmail.com | T16: თანამშრომელი_GUID
A17: 44182.056 | B17: ფალიაშვილის 63 (ს.კ. ICE000034) - ამხანაგობა | C17: Domus Paliashviliს 63 | D17: 1.1.1. (+) შემოსავალი ლიფტების რეალიზაციიდან | E17: 42948 | F17: 97000 | G17: GEL | H17: მიმდინარე | K17: ICE000034/42948/1.1.1./1 | L17: C897938C-00C4-4220-BAF1-CA29F3237D16 | M17: Domus Paliashviliს 63 | 1.1.1. (+) შემოსავალი ლიფტების რეალიზაციიდან | ფალიაშვილის 63 (ს.კ. ICE000034) - ამხანაგობა | N17: B59170EC-16CC-499A-9FF7-0428DCB8F727 | O17: 7F0A41E4-FA68-43E7-A979-126560D14B58 | Q17: gio.nikabadze@gmail.com | T17: [Collateral]
A18: 44182.056 | B18: ეკომეტრი (ს.კ. 404464030) - შპს | C18: Gelovani 52 | D18: 1.1.1. (+) შემოსავალი ლიფტების რეალიზაციიდან | E18: 42923 | F18: 161000 | G18: USD | H18: მიმდინარე | K18: 404464030/42923/1.1.1./1 | L18: 196F7BB2-781C-4FF2-BAEE-C30045DA8E1E | M18: Gelovani 52 | 1.1.1. (+) შემოსავალი ლიფტების რეალიზაციიდან | ეკომეტრი (ს.კ. 404464030) - შპს | N18: B59170EC-16CC-499A-9FF7-0428DCB8F727 | O18: B25EF46E-8022-4949-A1EB-E8A1256C7A3B | Q18: gio.nikabadze@gmail.com
A19: 44182.056 | B19: ჩემპიონი 2 (ს.კ. 248416432) - შპს | C19: Chempioni | D19: 1.1.1. (+) შემოსავალი ლიფტების რეალიზაციიდან | E19: 42536 | F19: 23924 | G19: USD | H19: მიმდინარე | K19: 248416432/42536/1.1.1./1 | L19: 42197EB0-C73A-4679-8D11-1DD3BAC96135 | M19: Chempioni | 1.1.1. (+) შემოსავალი ლიფტების რეალიზაციიდან | ჩემპიონი 2 (ს.კ. 248416432) - შპს | N19: B59170EC-16CC-499A-9FF7-0428DCB8F727 | O19: 967EE73E-8B77-4A8F-9FD3-AA36FF0ECB17 | Q19: gio.nikabadze@gmail.com
A20: 44182.056 | B20: ნიუ თაიმ (ს.კ. 445440577) - შპს | C20: New Time | D20: 1.1.1. (+) შემოსავალი ლიფტების რეალიზაციიდან | E20: 42885 | F20: 150000 | G20: USD | H20: მიმდინარე | K20: 445440577/42885/1.1.1./1 | L20: 7A83BC1F-C807-436E-9390-775B1D423BFD | M20: New Time | 1.1.1. (+) შემოსავალი ლიფტების რეალიზაციიდან | ნიუ თაიმ (ს.კ. 445440577) - შპს | N20: B59170EC-16CC-499A-9FF7-0428DCB8F727 | O20: EEF69DEA-9E1B-41C3-B563-3922DCE0A9BD | Q20: gio.nikabadze@gmail.com
A21: 44182.056 | B21: ელტური-2008 (ს.კ. 248434038) - შპს | C21: Green Cape | D21: 1.1.1. (+) შემოსავალი ლიფტების რეალიზაციიდან | E21: 43460 | F21: 70360 | G21: USD | H21: მიმდინარე | K21: 248434038/43460/1.1.1./1 | L21: D9285AF5-11A4-4764-B11B-745E9DAF1D34 | M21: Green Cape | 1.1.1. (+) შემოსავალი ლიფტების რეალიზაციიდან | ელტური-2008 (ს.კ. 248434038) - შპს | N21: B59170EC-16CC-499A-9FF7-0428DCB8F727 | O21: 0A7F5182-3B4F-4292-8569-FC31854BA5B4 | Q21: gio.nikabadze@gmail.com | T21: =TEXTJOIN("','",TRUE,Projects!B1:Q1) -> კონტრაგენტი :','პროექტის დასახელება :','შემოსავლის კოდი :','თარიღი :','თანხა :','ვალუტა :','პროექტის სტატუსი :','თანამშრომელი :','ORIS 1630 :','კონტრაქტის # - ','პროექტი_GUID/','პროექტი//','შემოსავლის კოდი_GUID','კონტრაგენტი_GUID','თანამშრომელი_GUID','Collateral
A22: 44182.056 | B22: ინდეკო (ს.კ. 202376133) - შპს | C22: Indeko - shartava 39 | D22: 1.1.1. (+) შემოსავალი ლიფტების რეალიზაციიდან | E22: 43460 | F22: 155520 | G22: USD | H22: მიმდინარე | K22: 202376133/42345/1.1.1./1 | L22: C5E1547A-8529-495B-974D-92544D0F1C66 | M22: Indeko - shartava 39 | 1.1.1. (+) შემოსავალი ლიფტების რეალიზაციიდან | ინდეკო (ს.კ. 202376133) - შპს | N22: B59170EC-16CC-499A-9FF7-0428DCB8F727 | O22: 8E8E99BE-75FC-49EC-9D89-960E30E7CB06 | Q22: gio.nikabadze@gmail.com
A23: 44182.056 | B23: რედ-კო (ს.კ. 405148415) - შპს | C23: Redco 1 | D23: 1.1.1. (+) შემოსავალი ლიფტების რეალიზაციიდან | E23: 43248 | F23: 370000 | G23: USD | H23: მიმდინარე | J23: 1 6 30 917 2 | K23: 405148415/43248/1.1.1./1 | L23: D421D947-C097-4870-8EF1-C7F724377248 | M23: Redco 1 | 1.1.1. (+) შემოსავალი ლიფტების რეალიზაციიდან | რედ-კო (ს.კ. 405148415) - შპს | N23: B59170EC-16CC-499A-9FF7-0428DCB8F727 | O23: DA9D440B-CACD-4076-8B91-BFFCA46814B6 | Q23: gio.nikabadze@gmail.com
A24: 44182.056 | B24: ბიზნეს ცენტრი დელისი (ს.კ. 204854014) - სს | C24: Delisi | D24: 1.1.1. (+) შემოსავალი ლიფტების რეალიზაციიდან | E24: 42598 | F24: 53454 | G24: USD | H24: მიმდინარე | K24: 204854014/42598/1.1.1./1 | L24: 2496A0E0-1118-49DC-8A82-539003DC1B23 | M24: Delisi | 1.1.1. (+) შემოსავალი ლიფტების რეალიზაციიდან | ბიზნეს ცენტრი დელისი (ს.კ. 204854014) - სს | N24: B59170EC-16CC-499A-9FF7-0428DCB8F727 | O24: 62F6C15C-8FCC-4A60-B37E-8A3DE9D20A48 | Q24: gio.nikabadze@gmail.com
A25: 44182.056 | B25: შველა (ს.კ. 448396021) - შპს | C25: Shvela | D25: 1.1.1. (+) შემოსავალი ლიფტების რეალიზაციიდან | E25: 42536 | F25: 50206 | G25: USD | H25: მიმდინარე | K25: 448396021/42536/1.1.1./1 | L25: 1C2CAB23-3967-41F9-AC61-62415AE0373C | M25: Shvela | 1.1.1. (+) შემოსავალი ლიფტების რეალიზაციიდან | შველა (ს.კ. 448396021) - შპს | N25: B59170EC-16CC-499A-9FF7-0428DCB8F727 | O25: A5C44F5D-1F9C-4BC1-BD39-C8B2E88BC49A | Q25: gio.nikabadze@gmail.com
A26: 44182.056 | B26: ბკ კაპიტალი (ს.კ. 205057123) - შპს | C26: Moxy Zaabruken Hotel | D26: 1.1.1. (+) შემოსავალი ლიფტების რეალიზაციიდან | E26: 42647 | F26: 157608.67 | G26: USD | H26: მიმდინარე | K26: 205057123/42647/1.1.1./1 | L26: 202843CA-C5C3-4057-8040-234B6C369B5E | M26: Moxy Zaabruken Hotel | 1.1.1. (+) შემოსავალი ლიფტების რეალიზაციიდან | ბკ კაპიტალი (ს.კ. 205057123) - შპს | N26: B59170EC-16CC-499A-9FF7-0428DCB8F727 | O26: D57E2878-F57C-4B96-B89E-A8B81F35634A | Q26: gio.nikabadze@gmail.com
A27: 44182.056 | B27: ინჟინერთა ჯგუფი (ს.კ. 400101457) - შპს | C27: Tbilisi Gardens | D27: 1.1.1. (+) შემოსავალი ლიფტების რეალიზაციიდან | E27: 42723 | F27: 325000 | G27: USD | H27: მიმდინარე | K27: 400101457/42723/1.1.1./1 | L27: 8C8C52A5-1A7C-485F-9AC8-043862EF3D55 | M27: Tbilisi Gardens | 1.1.1. (+) შემოსავალი ლიფტების რეალიზაციიდან | ინჟინერთა ჯგუფი (ს.კ. 400101457) - შპს | N27: B59170EC-16CC-499A-9FF7-0428DCB8F727 | O27: 2ED6F730-5337-4222-94F9-284E801BCE61 | Q27: gio.nikabadze@gmail.com
A28: 44182.056 | B28: მოდუსი (ს.კ. 245565669) - შპს | C28: Modus Kakhety HW | D28: 1.1.1. (+) შემოსავალი ლიფტების რეალიზაციიდან | E28: 42641 | F28: 25000 | G28: USD | H28: მიმდინარე | K28: 245565669/42641/1.1.1./1 | L28: BFD4409A-7F01-4C7C-9F40-73A80C2E63A6 | M28: Modus Kakhety HW | 1.1.1. (+) შემოსავალი ლიფტების რეალიზაციიდან | მოდუსი (ს.კ. 245565669) - შპს | N28: B59170EC-16CC-499A-9FF7-0428DCB8F727 | O28: 9729C88B-F3C5-441A-8782-0656302A37F2 | Q28: gio.nikabadze@gmail.com
A29: 44182.056 | B29: სითი დეველოპმენტ (ს.კ. 404481324) - შპს | C29: Kbuleti Str. - Khomeriki | D29: 1.1.1. (+) შემოსავალი ლიფტების რეალიზაციიდან | E29: 42485 | F29: 36577 | G29: USD | H29: მიმდინარე | K29: 404481324/42485/1.1.1./1 | L29: A53105CE-1BDB-4625-B775-A01DA1F6C8AD | M29: Kbuleti Str. - Khomeriki | 1.1.1. (+) შემოსავალი ლიფტების რეალიზაციიდან | სითი დეველოპმენტ (ს.კ. 404481324) - შპს | N29: B59170EC-16CC-499A-9FF7-0428DCB8F727 | O29: 57A60218-744B-4922-BF21-F9C52A01DAF6 | Q29: gio.nikabadze@gmail.com
A30: 44182.056 | B30: დომუს დეველოპმენტ (ს.კ. 205210261) - შპს | C30: Domus | D30: 1.1.1. (+) შემოსავალი ლიფტების რეალიზაციიდან | E30: 42355 | F30: 527700 | G30: USD | H30: მიმდინარე | K30: 205210261/42355/1.1.1./1 | L30: F154242F-E028-49D8-B7BE-42EB31281CD5 | M30: Domus | 1.1.1. (+) შემოსავალი ლიფტების რეალიზაციიდან | დომუს დეველოპმენტ (ს.კ. 205210261) - შპს | N30: B59170EC-16CC-499A-9FF7-0428DCB8F727 | O30: A3C5943B-D1C3-4CB2-946C-86BF678B6183 | Q30: gio.nikabadze@gmail.com
A31: 44182.056 | B31: ირაკლი კაციტაძე (ს.კ. 01008004604) - ფიზ. პირი | C31: Paliashvili 23 | D31: 1.1.2. (+) შემოსავალი ლიფტების სერვისიდან - გეგმიური | E31: 43831 | F31: 1 | G31: GEL | H31: მიმდინარე | K31: 01008004604/43831/1.1.2./1 | L31: 6D999F5B-2199-4578-A47D-FDC2DF179273 | M31: Paliashvili 23 | 1.1.2. (+) შემოსავალი ლიფტების სერვისიდან - გეგმიური | ირაკლი კაციტაძე (ს.კ. 01008004604) - ფიზ. პირი | N31: 12238130-9D12-4099-A48B-9EB5A085E0F8 | O31: 9AE0C821-91FF-44A4-90E6-F71F98BC044C | Q31: gio.nikabadze@gmail.com
A32: 44182.056 | B32: ბკ კაპიტალი (ს.კ. 205057123) - შპს | C32: Moxy Zabruken Restaurant | D32: 1.1.1. (+) შემოსავალი ლიფტების რეალიზაციიდან | E32: 43742 | F32: 78804.33 | G32: USD | H32: მიმდინარე | K32: 205057123/43742/1.1.1./1 | L32: 5E543EA8-4A6A-4F8C-9F72-071B61F85EEB | M32: Moxy Zabruken Restaurant | 1.1.1. (+) შემოსავალი ლიფტების რეალიზაციიდან | ბკ კაპიტალი (ს.კ. 205057123) - შპს | N32: B59170EC-16CC-499A-9FF7-0428DCB8F727 | O32: D57E2878-F57C-4B96-B89E-A8B81F35634A | Q32: gio.nikabadze@gmail.com
A33: 44182.056 | B33: ორბი ჯგუფი ბათუმი (ს.კ. 445468798) - შპს | C33: TWIN TOWER | D33: 1.1.1. (+) შემოსავალი ლიფტების რეალიზაციიდან | E33: 43059 | F33: 3273908 | G33: USD | H33: მიმდინარე | J33: 1 6 30 773 1 | K33: 445468798/43059/1.1.1./1 | L33: C35D9FF1-3A09-4634-9BFA-87C709266063 | M33: TWIN TOWER | 1.1.1. (+) შემოსავალი ლიფტების რეალიზაციიდან | ორბი ჯგუფი ბათუმი (ს.კ. 445468798) - შპს | N33: B59170EC-16CC-499A-9FF7-0428DCB8F727 | O33: E284E0FD-A2B7-4D93-8E91-006FF0A8A4CE | Q33: gio.nikabadze@gmail.com
A34: 44182.056 | B34: აი ჯი დეველოფმენტ ჯორჯია (ს.კ. 404851503) - შპს | C34: City Mall | D34: 1.1.1. (+) შემოსავალი ლიფტების რეალიზაციიდან | E34: 43354 | F34: 1194345 | G34: USD | H34: მიმდინარე | J34: 1 6 30 971 | K34: 404851503/43354/1.1.1./1 | L34: EA15EDA6-F906-4932-87BA-DDB8898D4EBC | M34: City Mall | 1.1.1. (+) შემოსავალი ლიფტების რეალიზაციიდან | აი ჯი დეველოფმენტ ჯორჯია (ს.კ. 404851503) - შპს | N34: B59170EC-16CC-499A-9FF7-0428DCB8F727 | O34: DDFBBDF4-5DA2-4BD2-918A-77AAF121BF72 | Q34: gio.nikabadze@gmail.com
A35: 44182.056 | B35: რენთინგ ბიენბი (ს.კ. 404564244) - სს | C35: Renting BNB | D35: 1.1.1. (+) შემოსავალი ლიფტების რეალიზაციიდან | E35: 43886 | F35: 26000 | G35: USD | H35: მიმდინარე | K35: 404564244/43886/1.1.1./1 | L35: 55F53FA9-CDDE-4FBA-91A1-FEAFA51B29A0 | M35: Renting BNB | 1.1.1. (+) შემოსავალი ლიფტების რეალიზაციიდან | რენთინგ ბიენბი (ს.კ. 404564244) - სს | N35: B59170EC-16CC-499A-9FF7-0428DCB8F727 | O35: 9B349A17-7CE1-4232-98C6-02C565C3642C | Q35: gio.nikabadze@gmail.com
A36: 44182.056 | B36: ტრანსმშენი (ს.კ. 212274812) - სს | C36: Aeroporti | D36: 1.1.1. (+) შემოსავალი ლიფტების რეალიზაციიდან | E36: 43699 | F36: 20000 | G36: USD | H36: მიმდინარე | K36: 212274812/43699/1.1.1./1 | L36: 44F2F4A0-908E-42D1-B73F-04859CACCB08 | M36: Aeroporti | 1.1.1. (+) შემოსავალი ლიფტების რეალიზაციიდან | ტრანსმშენი (ს.კ. 212274812) - სს | N36: B59170EC-16CC-499A-9FF7-0428DCB8F727 | O36: 9B21D54A-56D8-405D-95E2-A05872C7C1E9 | Q36: gio.nikabadze@gmail.com
A37: 44182.056 | B37: ბეტა ჯგუფი (ს.კ. 405171996) - შპს | C37: Dividers Med Uni | D37: 1.1.1. (+) შემოსავალი ლიფტების რეალიზაციიდან | E37: 43477 | F37: 11000 | G37: GEL | H37: მიმდინარე | K37: 405171996/43477/1.1.1./1 | L37: 2F958FC8-AC98-416D-BEAC-E4C6006FCCB3 | M37: Dividers Med Uni | 1.1.1. (+) შემოსავალი ლიფტების რეალიზაციიდან | ბეტა ჯგუფი (ს.კ. 405171996) - შპს | N37: B59170EC-16CC-499A-9FF7-0428DCB8F727 | O37: 3029E0C5-9337-4596-87DB-0A677D44A180 | Q37: gio.nikabadze@gmail.com
A38: 44182.056 | B38: ლუდსახარში ორი კათხა (ს.კ. 406283338) - შპს | C38: Brewery 1 (300KG) | D38: 1.1.1. (+) შემოსავალი ლიფტების რეალიზაციიდან | E38: 43896 | F38: 10610 | G38: USD | H38: მიმდინარე | K38: 406283338/43896/1.1.1./1 | L38: 4DB7E760-9ECD-4426-BB50-E293E58D2B02 | M38: Brewery 1 (300KG) | 1.1.1. (+) შემოსავალი ლიფტების რეალიზაციიდან | ლუდსახარში ორი კათხა (ს.კ. 406283338) - შპს | N38: B59170EC-16CC-499A-9FF7-0428DCB8F727 | O38: 1C2A10A9-FA2F-437B-8C70-F109D1C009EE | Q38: gio.nikabadze@gmail.com
A39: 44182.056 | B39: ახალშენი 2016 (ს.კ. 405136758) - შპს | C39: Khiliani | D39: 1.1.1. (+) შემოსავალი ლიფტების რეალიზაციიდან | E39: 43677 | F39: 26400 | G39: USD | H39: მიმდინარე | K39: 405136758/43677/1.1.1./1 | L39: E136ACFA-DBED-49EE-B224-24513754542C | M39: Khiliani | 1.1.1. (+) შემოსავალი ლიფტების რეალიზაციიდან | ახალშენი 2016 (ს.კ. 405136758) - შპს | N39: B59170EC-16CC-499A-9FF7-0428DCB8F727 | O39: 04FB28EA-5501-4B01-BA1D-C2955C0E1213 | Q39: gio.nikabadze@gmail.com
A40: 44182.056 | B40: ორბი ჯგუფი ბათუმი (ს.კ. 445468798) - შპს | C40: ORBI Office Lift | D40: 1.1.1. (+) შემოსავალი ლიფტების რეალიზაციიდან | E40: 43788 | F40: 30000 | G40: USD | H40: მიმდინარე | K40: 445468798/43788/1.1.1./1 | L40: 5B0BA252-1105-4374-8654-430AE04E8A64 | M40: ORBI Office Lift | 1.1.1. (+) შემოსავალი ლიფტების რეალიზაციიდან | ორბი ჯგუფი ბათუმი (ს.კ. 445468798) - შპს | N40: B59170EC-16CC-499A-9FF7-0428DCB8F727 | O40: E284E0FD-A2B7-4D93-8E91-006FF0A8A4CE | Q40: gio.nikabadze@gmail.com
...

Sheet Projects
A1: Timestamp | B1: კონტრაგენტი : | C1: პროექტის დასახელება : | D1: შემოსავლის კოდი : | E1: თარიღი : | F1: თანხა : | G1: ვალუტა : | H1: პროექტის სტატუსი : | I1: თანამშრომელი : | J1: ORIS 1630 : | K1: კონტრაქტის # - | L1: პროექტი_GUID/ | M1: პროექტი// | N1: შემოსავლის კოდი_GUID | O1: კონტრაგენტი_GUID | P1: თანამშრომელი_GUID | Q1: Collateral | R1: Deleted | S1: Name1 | T1: კონტრაგენტის ORIS ID | U1: {=if(A:A<>"",if(ROW(A:A)=1,"ნომერი","ICE"&row(A:A)-1),"")} -> ნომერი
A2: 44342.728 | B2: ოლიმპ ჯორჯია (ს.კ. 405231011) - შპს | C2: Biota Park | D2: 1.1.1. (+) შემოსავალი ლიფტების რეალიზაციიდან | E2: 43767 | F2: 350000 | G2: USD | H2: მიმდინარე | J2: 1 6 30 1270 | K2: 405231011/43767/1.1.1./1 | L2: 26A47FBE-6B71-4D89-B27B-4629DEEA1D34 | M2: Biota Park | 1.1.1. (+) შემოსავალი ლიფტების რეალიზაციიდან | ოლიმპ ჯორჯია (ს.კ. 405231011) - შპს | N2: B59170EC-16CC-499A-9FF7-0428DCB8F727 | O2: 6DECD64D-60DA-49AE-A9B3-49D7E02F2D62 | Q2: gio.nikabadze@gmail.com | S2: {=if(A2:A1450<>"",left(M2:M1450,iferror(search("(+)",M2:M1450),search("(-)",M2:M1450))-2)&" "&MID(M2:M1450,SEARCH("|",M2:M1450),1)&" "&left(B2:B1450,SEARCH("(ს.კ.",B2:B1450)-1)&" "&MID(M2:M1450,SEARCH("|",M2:M1450),1)&" "&TEXT(F2:F1450,"#,##0.00")&" "&G2:G1450&" "&MID(M2:M1450,SEARCH("|",M2:M1450),1)&" "&TEXT(E2:E1450,"DD.MM.YYYY"),"")} -> Biota Park | 1.1.1. | ოლიმპ ჯორჯია | 350,000.00 USD | 29.10.2019 | T2: =IFERROR(__xludf.DUMMYFUNCTION("ArrayFormula(if( A2:A1450<>"""", vlookup(O2:O1450, QUERY(IMPORTRANGE(""1BB2vegyweFMhmEGshLTiUL8CE4mOZ6zsta5ECrU9TU0"",""Counteragents""&""!A:Z""),CONCATENATE(""Select Col"",MATCH(""კონტრაგენტი_GUID/"",IMPORTRANGE(""1a0yHMlSrZV71Un45oznplcEPzNjsl78Qko9uBFT"&"PIUA"",""Counteragents!1:1""),0),"", Col"",MATCH(""ORIS ID :"",IMPORTRANGE(""1a0yHMlSrZV71Un45oznplcEPzNjsl78Qko9uBFTPIUA"",""Counteragents!1:1""),0))),2,FALSE),""""))"),1270.0) -> 1270 | U2: ICE1
A3: 44342.729 | B3: ინდეკო (ს.კ. 202376133) - შპს | C3: Chakhrukhadze | D3: 1.1.1. (+) შემოსავალი ლიფტების რეალიზაციიდან | E3: 43762 | F3: 23100 | G3: USD | H3: მიმდინარე | J3: 1 6 30 541 4 | K3: 202376133/43762/1.1.1./1 | L3: BFCA9047-3C75-4EEB-9FE8-82617FFD3965 | M3: Chakhrukhadze | 1.1.1. (+) შემოსავალი ლიფტების რეალიზაციიდან | ინდეკო (ს.კ. 202376133) - შპს | N3: B59170EC-16CC-499A-9FF7-0428DCB8F727 | O3: 8E8E99BE-75FC-49EC-9D89-960E30E7CB06 | Q3: gio.nikabadze@gmail.com | S3: Chakhrukhadze | 1.1.1. | ინდეკო | 23,100.00 USD | 24.10.2019 | T3: =IFERROR(__xludf.DUMMYFUNCTION("""COMPUTED_VALUE"""),541.0) -> 541 | U3: ICE2
A4: 44342.729 | B4: ბეტა ჯგუფი (ს.კ. 405171996) - შპს | C4: Med. University | D4: 1.1.1. (+) შემოსავალი ლიფტების რეალიზაციიდან | E4: 43767 | F4: 42500 | G4: USD | H4: მიმდინარე | K4: 405171996/43767/1.1.1./1 | L4: 00664103-FB2D-4EA7-A2B7-28064D745999 | M4: Med. University | 1.1.1. (+) შემოსავალი ლიფტების რეალიზაციიდან | ბეტა ჯგუფი (ს.კ. 405171996) - შპს | N4: B59170EC-16CC-499A-9FF7-0428DCB8F727 | O4: 3029E0C5-9337-4596-87DB-0A677D44A180 | Q4: gio.nikabadze@gmail.com | S4: Med. University | 1.1.1. | ბეტა ჯგუფი | 42,500.00 USD | 29.10.2019 | T4: =IFERROR(__xludf.DUMMYFUNCTION("""COMPUTED_VALUE"""),1257.0) -> 1257 | U4: ICE3
A5: 44342.729 | B5: გიოკაპიტალი (ს.კ. 406155841) - შპს | C5: Varketili | D5: 1.1.1. (+) შემოსავალი ლიფტების რეალიზაციიდან | E5: 43724 | F5: 48500 | G5: USD | H5: მიმდინარე | J5: 1 6 30 1252 | K5: 406155841/43724/1.1.1./1 | L5: 80851DA9-84C4-4C2C-95FE-D6A0282F7B22 | M5: Varketili | 1.1.1. (+) შემოსავალი ლიფტების რეალიზაციიდან | გიოკაპიტალი (ს.კ. 406155841) - შპს | N5: B59170EC-16CC-499A-9FF7-0428DCB8F727 | O5: 97BEEA92-7829-4A09-8B1C-D0FE871340D4 | Q5: gio.nikabadze@gmail.com | S5: Varketili | 1.1.1. | გიოკაპიტალი | 48,500.00 USD | 16.09.2019 | T5: =IFERROR(__xludf.DUMMYFUNCTION("""COMPUTED_VALUE"""),1252.0) -> 1252 | U5: ICE4
A6: 44342.729 | B6: რედ-კო (ს.კ. 405148415) - შპს | C6: Gudauri Redco Parking | D6: 1.1.1. (+) შემოსავალი ლიფტების რეალიზაციიდან | E6: 43734 | F6: 28000 | G6: USD | H6: მიმდინარე | K6: 405148415/43734/1.1.1./1 | L6: 2E1DDD27-332A-4E4A-B571-52B4DE3B8E04 | M6: Gudauri Redco Parking | 1.1.1. (+) შემოსავალი ლიფტების რეალიზაციიდან | რედ-კო (ს.კ. 405148415) - შპს | N6: B59170EC-16CC-499A-9FF7-0428DCB8F727 | O6: DA9D440B-CACD-4076-8B91-BFFCA46814B6 | Q6: gio.nikabadze@gmail.com | S6: Gudauri Redco Parking | 1.1.1. | რედ-კო | 28,000.00 USD | 26.09.2019 | T6: =IFERROR(__xludf.DUMMYFUNCTION("""COMPUTED_VALUE"""),917.0) -> 917 | U6: ICE5
A7: 44342.729 | B7: მაია კვიჭიძე (ს.კ. 01008011243) - ფიზ. პირი | C7: Ortachala | D7: 1.1.1. (+) შემოსავალი ლიფტების რეალიზაციიდან | E7: 43672 | F7: 24000 | G7: USD | H7: მიმდინარე | K7: 01008011243/43672/1.1.1./1 | L7: 83FEC832-A4EA-4380-B5E9-85BEEECE8FA4 | M7: Ortachala | 1.1.1. (+) შემოსავალი ლიფტების რეალიზაციიდან | მაია კვიჭიძე (ს.კ. 01008011243) - ფიზ. პირი | N7: B59170EC-16CC-499A-9FF7-0428DCB8F727 | O7: D5136DB7-C17A-4DDB-9797-D1B10612D28C | Q7: gio.nikabadze@gmail.com | S7: Ortachala | 1.1.1. | მაია კვიჭიძე | 24,000.00 USD | 26.07.2019 | T7: =IFERROR(__xludf.DUMMYFUNCTION("""COMPUTED_VALUE"""),1207.0) -> 1207 | U7: ICE6
A8: 44342.729 | B8: მოდუსი (ს.კ. 245565669) - შპს | C8: Modus Agladze | D8: 1.1.1. (+) შემოსავალი ლიფტების რეალიზაციიდან | E8: 43633 | F8: 32000 | G8: USD | H8: მიმდინარე | K8: 245565669/43633/1.1.1./1 | L8: ABDEF9CC-F0E1-4950-B30C-D46A8A8A912C | M8: Modus Agladze | 1.1.1. (+) შემოსავალი ლიფტების რეალიზაციიდან | მოდუსი (ს.კ. 245565669) - შპს | N8: B59170EC-16CC-499A-9FF7-0428DCB8F727 | O8: 9729C88B-F3C5-441A-8782-0656302A37F2 | Q8: gio.nikabadze@gmail.com | S8: Modus Agladze | 1.1.1. | მოდუსი | 32,000.00 USD | 17.06.2019 | T8: =IFERROR(__xludf.DUMMYFUNCTION("""COMPUTED_VALUE"""),642.0) -> 642 | U8: ICE7
A9: 44342.729 | B9: ჰომბეი (ს.კ. 405255815) - შპს | C9: Crystal Bakuriani | D9: 1.1.1. (+) შემოსავალი ლიფტების რეალიზაციიდან | E9: 43608 | F9: 104500 | G9: USD | H9: მიმდინარე | K9: 405255815/43608/1.1.1./1 | L9: 230FCB1B-1310-4C49-9D2C-9CD5F9A792A3 | M9: Crystal Bakuriani | 1.1.1. (+) შემოსავალი ლიფტების რეალიზაციიდან | ჰომბეი (ს.კ. 405255815) - შპს | N9: B59170EC-16CC-499A-9FF7-0428DCB8F727 | O9: AAFC235A-2BBF-4CEC-A2AE-F1AEBABC12E4 | Q9: gio.nikabadze@gmail.com | S9: Crystal Bakuriani | 1.1.1. | ჰომბეი | 104,500.00 USD | 23.05.2019 | T9: =IFERROR(__xludf.DUMMYFUNCTION("""COMPUTED_VALUE"""),1173.0) -> 1173 | U9: ICE8
A10: 44342.729 | B10: ანა აბუსერიძე (ს.კ. 61001051501) - ფიზ. პირი | C10: Abuseridze - Batumi | D10: 1.1.1. (+) შემოსავალი ლიფტების რეალიზაციიდან | E10: 43622 | F10: 31000 | G10: USD | H10: მიმდინარე | J10: 1 6 30 1179 | K10: 61001051501/43622/1.1.1./1 | L10: 4E89F135-A0AD-4622-97BD-7B68EF6062F8 | M10: Abuseridze - Batumi | 1.1.1. (+) შემოსავალი ლიფტების რეალიზაციიდან | ანა აბუსერიძე (ს.კ. 61001051501) - ფიზ. პირი | N10: B59170EC-16CC-499A-9FF7-0428DCB8F727 | O10: 15F35EBB-5A28-4C1B-B7CC-45FF3F31D4D6 | Q10: gio.nikabadze@gmail.com | S10: Abuseridze - Batumi | 1.1.1. | ანა აბუსერიძე | 31,000.00 USD | 06.06.2019 | T10: =IFERROR(__xludf.DUMMYFUNCTION("""COMPUTED_VALUE"""),1179.0) -> 1179 | U10: ICE9
A11: 44342.729 | B11: იუნიქს ქონსთრაქშენ კომპანი (ს.კ. 405133822) - შპს | C11: UNIX Marselle | D11: 1.1.1. (+) შემოსავალი ლიფტების რეალიზაციიდან | E11: 43607 | F11: 340000 | G11: USD | H11: მიმდინარე | K11: 405133822/43607/1.1.1./1 | L11: CFFC1C06-B78B-45A0-8A02-37A23706EAFC | M11: UNIX Marselle | 1.1.1. (+) შემოსავალი ლიფტების რეალიზაციიდან | იუნიქს ქონსთრაქშენ კომპანი (ს.კ. 405133822) - შპს | N11: B59170EC-16CC-499A-9FF7-0428DCB8F727 | O11: B4968862-3843-414D-9E73-1A7611618B41 | Q11: gio.nikabadze@gmail.com | S11: UNIX Marselle | 1.1.1. | იუნიქს ქონსთრაქშენ კომპანი | 340,000.00 USD | 22.05.2019 | T11: =IFERROR(__xludf.DUMMYFUNCTION("""COMPUTED_VALUE"""),902.0) -> 902 | U11: ICE10
A12: 44342.729 | B12: თბილისი პალასი (ს.კ. 405253381) - შპს | C12: Tbilisi Palace | D12: 1.1.1. (+) შემოსავალი ლიფტების რეალიზაციიდან | E12: 43460 | F12: 160000 | G12: USD | H12: მიმდინარე | K12: 405253381/43460/1.1.1./1 | L12: 125722B7-4DB0-4817-B1A4-DBA0B1B893D4 | M12: Tbilisi Palace | 1.1.1. (+) შემოსავალი ლიფტების რეალიზაციიდან | თბილისი პალასი (ს.კ. 405253381) - შპს | N12: B59170EC-16CC-499A-9FF7-0428DCB8F727 | O12: 3F5B4217-38D4-4FB8-B3F3-E856A10FFF06 | Q12: gio.nikabadze@gmail.com | S12: Tbilisi Palace | 1.1.1. | თბილისი პალასი | 160,000.00 USD | 26.12.2018 | T12: =IFERROR(__xludf.DUMMYFUNCTION("""COMPUTED_VALUE"""),1034.0) -> 1034 | U12: ICE11
A13: 44342.729 | B13: თეგეტა მოტორსი (ს.კ. 202177205) - შპს | C13: Tegeta Batumi | D13: 1.1.1. (+) შემოსავალი ლიფტების რეალიზაციიდან | E13: 43479 | F13: 28650 | G13: USD | H13: მიმდინარე | K13: 202177205/43479/1.1.1./1 | L13: 255604D7-5424-4548-9CAA-ECFF960BB6AE | M13: Tegeta Batumi | 1.1.1. (+) შემოსავალი ლიფტების რეალიზაციიდან | თეგეტა მოტორსი (ს.კ. 202177205) - შპს | N13: B59170EC-16CC-499A-9FF7-0428DCB8F727 | O13: 5A21C207-4868-4EA6-9B48-5D0F743D5535 | Q13: gio.nikabadze@gmail.com | S13: Tegeta Batumi | 1.1.1. | თეგეტა მოტორსი | 28,650.00 USD | 14.01.2019 | T13: =IFERROR(__xludf.DUMMYFUNCTION("""COMPUTED_VALUE"""),93.0) -> 93 | U13: ICE12
A14: 44342.729 | B14: Dar Building (ს.კ. 445420875) - შპს | C14: DAR TOWER | D14: 1.1.1. (+) შემოსავალი ლიფტების რეალიზაციიდან | E14: 43363 | F14: 1046340 | G14: USD | H14: მიმდინარე | J14: 1 6 30 853 1 | K14: 445420875/43363/1.1.1./1 | L14: A4EE54E2-C9BC-44F8-8554-44B9037B38D2 | M14: DAR TOWER | 1.1.1. (+) შემოსავალი ლიფტების რეალიზაციიდან | Dar Building (ს.კ. 445420875) - შპს | N14: B59170EC-16CC-499A-9FF7-0428DCB8F727 | O14: 7BF4A039-29BC-44AC-A87D-E8832394B94E | Q14: gio.nikabadze@gmail.com | S14: DAR TOWER | 1.1.1. | Dar Building | 1,046,340.00 USD | 20.09.2018 | T14: =IFERROR(__xludf.DUMMYFUNCTION("""COMPUTED_VALUE"""),853.0) -> 853 | U14: ICE13
A15: 44342.729 | B15: ბათბილდინგი (ს.კ. 445509334) - შპს | C15: BAT Tower | D15: 1.1.1. (+) შემოსავალი ლიფტების რეალიზაციიდან | E15: 43461 | F15: 73000 | G15: USD | H15: მიმდინარე | J15: 1 6 30 1039 | K15: 445509334/43461/1.1.1./1 | L15: A7AFCD4C-CA26-464C-8F1B-E9A5240DCB0F | M15: BAT Tower | 1.1.1. (+) შემოსავალი ლიფტების რეალიზაციიდან | ბათბილდინგი (ს.კ. 445509334) - შპს | N15: B59170EC-16CC-499A-9FF7-0428DCB8F727 | O15: DAE7B000-963F-42D9-AA35-8F3F2F8A3716 | Q15: gio.nikabadze@gmail.com | S15: BAT Tower | 1.1.1. | ბათბილდინგი | 73,000.00 USD | 27.12.2018 | T15: =IFERROR(__xludf.DUMMYFUNCTION("""COMPUTED_VALUE"""),1039.0) -> 1039 | U15: ICE14
A16: 44342.729 | B16: რუმი (ს.კ. 445481853) - შპს | C16: Rumi - batumi | D16: 1.1.1. (+) შემოსავალი ლიფტების რეალიზაციიდან | E16: 43816 | F16: 117370 | G16: USD | H16: მიმდინარე | J16: 1 6 30 1335 | K16: 445481853/43816/1.1.1./1 | L16: E95274D6-921C-43D1-B7C4-4F99A71C4005 | M16: Rumi - batumi | 1.1.1. (+) შემოსავალი ლიფტების რეალიზაციიდან | რუმი (ს.კ. 445481853) - შპს | N16: B59170EC-16CC-499A-9FF7-0428DCB8F727 | O16: BFABDF11-34C8-4815-A840-47DD5AAB9F4F | Q16: gio.nikabadze@gmail.com | S16: Rumi - batumi | 1.1.1. | რუმი | 117,370.00 USD | 17.12.2019 | T16: =IFERROR(__xludf.DUMMYFUNCTION("""COMPUTED_VALUE"""),1335.0) -> 1335 | U16: ICE15
A17: 44342.729 | B17: ფალიაშვილის 63 (ს.კ. ICE000034) - ამხანაგობა | C17: Domus Paliashviliს 63 | D17: 1.1.1. (+) შემოსავალი ლიფტების რეალიზაციიდან | E17: 42948 | F17: 97000 | G17: GEL | H17: მიმდინარე | K17: ICE000034/42948/1.1.1./1 | L17: C897938C-00C4-4220-BAF1-CA29F3237D16 | M17: Domus Paliashviliს 63 | 1.1.1. (+) შემოსავალი ლიფტების რეალიზაციიდან | ფალიაშვილის 63 (ს.კ. ICE000034) - ამხანაგობა | N17: B59170EC-16CC-499A-9FF7-0428DCB8F727 | O17: 7F0A41E4-FA68-43E7-A979-126560D14B58 | Q17: gio.nikabadze@gmail.com | S17: Domus Paliashviliს 63 | 1.1.1. | ფალიაშვილის 63 | 97,000.00 GEL | 01.08.2017 | T17: =IFERROR(__xludf.DUMMYFUNCTION("""COMPUTED_VALUE"""),863.0) -> 863 | U17: ICE16
A18: 44342.729 | B18: ეკომეტრი (ს.კ. 404464030) - შპს | C18: Gelovani 52 | D18: 1.1.1. (+) შემოსავალი ლიფტების რეალიზაციიდან | E18: 42923 | F18: 161000 | G18: USD | H18: მიმდინარე | K18: 404464030/42923/1.1.1./1 | L18: 196F7BB2-781C-4FF2-BAEE-C30045DA8E1E | M18: Gelovani 52 | 1.1.1. (+) შემოსავალი ლიფტების რეალიზაციიდან | ეკომეტრი (ს.კ. 404464030) - შპს | N18: B59170EC-16CC-499A-9FF7-0428DCB8F727 | O18: B25EF46E-8022-4949-A1EB-E8A1256C7A3B | Q18: gio.nikabadze@gmail.com | S18: Gelovani 52 | 1.1.1. | ეკომეტრი | 161,000.00 USD | 07.07.2017 | T18: =IFERROR(__xludf.DUMMYFUNCTION("""COMPUTED_VALUE"""),710.0) -> 710 | U18: ICE17
A19: 44342.729 | B19: ჩემპიონი 2 (ს.კ. 248416432) - შპს | C19: Chempioni | D19: 1.1.1. (+) შემოსავალი ლიფტების რეალიზაციიდან | E19: 42536 | F19: 23924 | G19: USD | H19: მიმდინარე | K19: 248416432/42536/1.1.1./1 | L19: 42197EB0-C73A-4679-8D11-1DD3BAC96135 | M19: Chempioni | 1.1.1. (+) შემოსავალი ლიფტების რეალიზაციიდან | ჩემპიონი 2 (ს.კ. 248416432) - შპს | N19: B59170EC-16CC-499A-9FF7-0428DCB8F727 | O19: 967EE73E-8B77-4A8F-9FD3-AA36FF0ECB17 | Q19: gio.nikabadze@gmail.com | S19: Chempioni | 1.1.1. | ჩემპიონი 2 | 23,924.00 USD | 15.06.2016 | T19: =IFERROR(__xludf.DUMMYFUNCTION("""COMPUTED_VALUE"""),599.0) -> 599 | U19: ICE18
A20: 44342.729 | B20: ნიუ თაიმ (ს.კ. 445440577) - შპს | C20: New Time | D20: 1.1.1. (+) შემოსავალი ლიფტების რეალიზაციიდან | E20: 42885 | F20: 150000 | G20: USD | H20: მიმდინარე | K20: 445440577/42885/1.1.1./1 | L20: 7A83BC1F-C807-436E-9390-775B1D423BFD | M20: New Time | 1.1.1. (+) შემოსავალი ლიფტების რეალიზაციიდან | ნიუ თაიმ (ს.კ. 445440577) - შპს | N20: B59170EC-16CC-499A-9FF7-0428DCB8F727 | O20: EEF69DEA-9E1B-41C3-B563-3922DCE0A9BD | Q20: gio.nikabadze@gmail.com | S20: New Time | 1.1.1. | ნიუ თაიმ | 150,000.00 USD | 30.05.2017 | T20: =IFERROR(__xludf.DUMMYFUNCTION("""COMPUTED_VALUE"""),693.0) -> 693 | U20: ICE19
A21: 44342.729 | B21: ელტური-2008 (ს.კ. 248434038) - შპს | C21: Green Cape | D21: 1.1.1. (+) შემოსავალი ლიფტების რეალიზაციიდან | E21: 43460 | F21: 70360 | G21: USD | H21: მიმდინარე | K21: 248434038/43460/1.1.1./1 | L21: D9285AF5-11A4-4764-B11B-745E9DAF1D34 | M21: Green Cape | 1.1.1. (+) შემოსავალი ლიფტების რეალიზაციიდან | ელტური-2008 (ს.კ. 248434038) - შპს | N21: B59170EC-16CC-499A-9FF7-0428DCB8F727 | O21: 0A7F5182-3B4F-4292-8569-FC31854BA5B4 | Q21: gio.nikabadze@gmail.com | S21: Green Cape | 1.1.1. | ელტური-2008 | 70,360.00 USD | 26.12.2018 | T21: =IFERROR(__xludf.DUMMYFUNCTION("""COMPUTED_VALUE"""),1038.0) -> 1038 | U21: ICE20
A22: 44342.729 | B22: ინდეკო (ს.კ. 202376133) - შპს | C22: Indeko - shartava 39 | D22: 1.1.1. (+) შემოსავალი ლიფტების რეალიზაციიდან | E22: 43460 | F22: 155520 | G22: USD | H22: მიმდინარე | K22: 202376133/42345/1.1.1./1 | L22: C5E1547A-8529-495B-974D-92544D0F1C66 | M22: Indeko - shartava 39 | 1.1.1. (+) შემოსავალი ლიფტების რეალიზაციიდან | ინდეკო (ს.კ. 202376133) - შპს | N22: B59170EC-16CC-499A-9FF7-0428DCB8F727 | O22: 8E8E99BE-75FC-49EC-9D89-960E30E7CB06 | Q22: gio.nikabadze@gmail.com | S22: Indeko - shartava 39 | 1.1.1. | ინდეკო | 155,520.00 USD | 26.12.2018 | T22: =IFERROR(__xludf.DUMMYFUNCTION("""COMPUTED_VALUE"""),541.0) -> 541 | U22: ICE21
A23: 44342.729 | B23: რედ-კო (ს.კ. 405148415) - შპს | C23: Redco 1 | D23: 1.1.1. (+) შემოსავალი ლიფტების რეალიზაციიდან | E23: 43248 | F23: 370000 | G23: USD | H23: მიმდინარე | J23: 1 6 30 917 2 | K23: 405148415/43248/1.1.1./1 | L23: D421D947-C097-4870-8EF1-C7F724377248 | M23: Redco 1 | 1.1.1. (+) შემოსავალი ლიფტების რეალიზაციიდან | რედ-კო (ს.კ. 405148415) - შპს | N23: B59170EC-16CC-499A-9FF7-0428DCB8F727 | O23: DA9D440B-CACD-4076-8B91-BFFCA46814B6 | Q23: gio.nikabadze@gmail.com | S23: Redco 1 | 1.1.1. | რედ-კო | 370,000.00 USD | 28.05.2018 | T23: =IFERROR(__xludf.DUMMYFUNCTION("""COMPUTED_VALUE"""),917.0) -> 917 | U23: ICE22
A24: 44342.729 | B24: ბიზნეს ცენტრი დელისი (ს.კ. 204854014) - სს | C24: Delisi | D24: 1.1.1. (+) შემოსავალი ლიფტების რეალიზაციიდან | E24: 42598 | F24: 53454 | G24: USD | H24: მიმდინარე | K24: 204854014/42598/1.1.1./1 | L24: 2496A0E0-1118-49DC-8A82-539003DC1B23 | M24: Delisi | 1.1.1. (+) შემოსავალი ლიფტების რეალიზაციიდან | ბიზნეს ცენტრი დელისი (ს.კ. 204854014) - სს | N24: B59170EC-16CC-499A-9FF7-0428DCB8F727 | O24: 62F6C15C-8FCC-4A60-B37E-8A3DE9D20A48 | Q24: gio.nikabadze@gmail.com | S24: Delisi | 1.1.1. | ბიზნეს ცენტრი დელისი | 53,454.00 USD | 16.08.2016 | T24: =IFERROR(__xludf.DUMMYFUNCTION("""COMPUTED_VALUE"""),620.0) -> 620 | U24: ICE23
A25: 44342.729 | B25: შველა (ს.კ. 448396021) - შპს | C25: Shvela | D25: 1.1.1. (+) შემოსავალი ლიფტების რეალიზაციიდან | E25: 42536 | F25: 50206 | G25: USD | H25: მიმდინარე | K25: 448396021/42536/1.1.1./1 | L25: 1C2CAB23-3967-41F9-AC61-62415AE0373C | M25: Shvela | 1.1.1. (+) შემოსავალი ლიფტების რეალიზაციიდან | შველა (ს.კ. 448396021) - შპს | N25: B59170EC-16CC-499A-9FF7-0428DCB8F727 | O25: A5C44F5D-1F9C-4BC1-BD39-C8B2E88BC49A | Q25: gio.nikabadze@gmail.com | S25: Shvela | 1.1.1. | შველა | 50,206.00 USD | 15.06.2016 | T25: =IFERROR(__xludf.DUMMYFUNCTION("""COMPUTED_VALUE"""),595.0) -> 595 | U25: ICE24
