Workbook

Sheet Orders
A1: Date | B1: Sum | C1: ID_14 | D1: Comment | E1: Description | F1: IBAN | G1: Collateral | H1: Code | I1: Counteragent | J1: Project | K1: Job Type | L1: Income Tax | M1: Job | N1: Record GUID | O1: Timestamp | P1: User
A2: 46142.458 | B2: 25000 | C2: f3ce6e_a3_beadc9 | F2: 2 | G2: nikaelevator@gmail.com | H2: 1.1.1.5. (+) ლიფტების ჩაბარება | I2: ზ-გრუპ (ს.კ. 400017245) - შპს | J2: ZYGMA | 1.1.1. | ზ-გრუპ | 524,300.00 USD | 10.03.2025 | L2: FALSE | N2: 9b744368-f75c-456d-9a8e-9bdf1ba21169 | O2: 45744.657 | P2: nikaelevator@gmail.com
A3: 46142.458 | B3: 962 | C3: 5007c8_f0_b26d52 | F3: DummyIBAN | G3: nikaelevator@gmail.com | H3: 2.1.1.9. (-) ლიფტების მონტაჟის ბონუსები | I3: Budget Dummy (ს.კ. ICE002065) - შპს | J3: ZYGMA | 1.1.1. | ზ-გრუპ | 524,300.00 USD | 10.03.2025 | L3: FALSE | N3: 3447cfc3-e66b-443c-b7f2-82e9f0f949dd | O3: 45744.657 | P3: nikaelevator@gmail.com
A4: 46127.458 | B4: 25000 | C4: b83db5_84_b38688 | F4: 2 | G4: nikaelevator@gmail.com | H4: 1.1.1.4. (+) ლიფტების მონტაჟის პროგრესის ავანსი | I4: ზ-გრუპ (ს.კ. 400017245) - შპს | J4: ZYGMA | 1.1.1. | ზ-გრუპ | 524,300.00 USD | 10.03.2025 | L4: FALSE | N4: d97adbef-875b-4fb1-8e16-522e9cda263a | O4: 45744.657 | P4: nikaelevator@gmail.com
A5: 46127.458 | B5: 21200 | C5: fc79e7_85_8e7110 | F5: DummyIBAN | G5: nikaelevator@gmail.com | H5: 2.1.1.3. (-) ლიფტების მონტაჟის ღირებულება | I5: Budget Dummy (ს.კ. ICE002065) - შპს | J5: ZYGMA | 1.1.1. | ზ-გრუპ | 524,300.00 USD | 10.03.2025 | L5: TRUE | N5: 81759988-8d22-4a12-ad6d-94d4049106ab | O5: 45744.657 | P5: nikaelevator@gmail.com
A6: 46127.458 | B6: 1590 | C6: a6622d_06_a1a791 | F6: DummyIBAN | G6: nikaelevator@gmail.com | H6: 2.1.1.6. (-) ლიფტების მონტაჟის დამხმარე მასალები | I6: Budget Dummy (ს.კ. ICE002065) - შპს | J6: ZYGMA | 1.1.1. | ზ-გრუპ | 524,300.00 USD | 10.03.2025 | L6: FALSE | N6: 33461393-89c8-4877-9702-0ffa90130fb1 | O6: 45744.657 | P6: nikaelevator@gmail.com
A7: 46097.458 | B7: 22000 | C7: b9aaa8_9e_9285dc | F7: DummyIBAN | G7: nikaelevator@gmail.com | H7: 2.1.1.3. (-) ლიფტების მონტაჟის ღირებულება | I7: Budget Dummy (ს.კ. ICE002065) - შპს | J7: ZYGMA | 1.1.1. | ზ-გრუპ | 524,300.00 USD | 10.03.2025 | L7: TRUE | N7: b40bae34-6cd0-4dfb-bb52-929411b0f0da | O7: 45744.657 | P7: nikaelevator@gmail.com
A8: 46097.458 | B8: 1600 | C8: ba3047_8b_9b6889 | F8: DummyIBAN | G8: nikaelevator@gmail.com | H8: 2.1.1.6. (-) ლიფტების მონტაჟის დამხმარე მასალები | I8: Budget Dummy (ს.კ. ICE002065) - შპს | J8: ZYGMA | 1.1.1. | ზ-გრუპ | 524,300.00 USD | 10.03.2025 | L8: FALSE | N8: aa2fe372-6fa5-416f-8e39-71b791155e41 | O8: 45744.657 | P8: nikaelevator@gmail.com
A9: 46067.5 | B9: 22000 | C9: 777dd5_69_ba96e1 | F9: DummyIBAN | G9: nikaelevator@gmail.com | H9: 2.1.1.3. (-) ლიფტების მონტაჟის ღირებულება | I9: Budget Dummy (ს.კ. ICE002065) - შპს | J9: ZYGMA | 1.1.1. | ზ-გრუპ | 524,300.00 USD | 10.03.2025 | L9: TRUE | N9: cd17e642-3548-46e4-a2c7-b71991f829eb | O9: 45744.657 | P9: nikaelevator@gmail.com
A10: 46067.5 | B10: 1600 | C10: 67707d_5a_be6e2a | F10: DummyIBAN | G10: nikaelevator@gmail.com | H10: 2.1.1.6. (-) ლიფტების მონტაჟის დამხმარე მასალები | I10: Budget Dummy (ს.კ. ICE002065) - შპს | J10: ZYGMA | 1.1.1. | ზ-გრუპ | 524,300.00 USD | 10.03.2025 | L10: FALSE | N10: 751c23df-ddf7-4035-bfc5-7de5a0378a58 | O10: 45744.657 | P10: nikaelevator@gmail.com
A11: 46037.5 | B11: 222000 | C11: a3a1a2_f5_be4ae3 | F11: 2 | G11: nikaelevator@gmail.com | H11: 1.1.1.3. (+) ლიფტების საბაჟოზე შემოსვლის ან დასაწყობების ავანსი | I11: ზ-გრუპ (ს.კ. 400017245) - შპს | J11: ZYGMA | 1.1.1. | ზ-გრუპ | 524,300.00 USD | 10.03.2025 | L11: FALSE | N11: 0cf5880f-c4ef-447d-9952-3d8b37283c52 | O11: 45744.657 | P11: nikaelevator@gmail.com
A12: 46037.5 | B12: 36800 | C12: 3197b7_5d_9c197e | F12: DummyIBAN | G12: nikaelevator@gmail.com | H12: 2.1.1.2. (-) ლიფტების ტრანსპორტირება | I12: Budget Dummy (ს.კ. ICE002065) - შპს | J12: ZYGMA | 1.1.1. | ზ-გრუპ | 524,300.00 USD | 10.03.2025 | L12: FALSE | N12: aea3a925-c419-445a-be02-29db9c84a7a3 | O12: 45744.657 | P12: nikaelevator@gmail.com
A13: 46033.5 | B13: 6615 | C13: 5eecbc_3a_9cc4c3 | F13: 2 | G13: nikaelevator@gmail.com | H13: 1.1.1.5. (+) ლიფტების ჩაბარება | I13: ნამი 2024 (ს.კ. 405720019) - შპს | J13: Nami | 1.1.1. | ნამი 2024 | 66,150.00 USD | 16.04.2025 | L13: FALSE | N13: b49bc77e-fcce-4d9b-81f5-941bb5fea34f | O13: 45763.699 | P13: nikaelevator@gmail.com
A14: 46033.5 | B14: 1875 | C14: 1e93d0_c4_a2b384 | F14: DummyIBAN | G14: nikaelevator@gmail.com | H14: 2.1.1.3. (-) ლიფტების მონტაჟის ღირებულება | I14: Budget Dummy (ს.კ. ICE002065) - შპს | J14: Nami | 1.1.1. | ნამი 2024 | 66,150.00 USD | 16.04.2025 | L14: TRUE | N14: 1b8c55a4-acd0-4b17-97da-9bdd1b2d7110 | O14: 45763.699 | P14: nikaelevator@gmail.com
A15: 46033.5 | B15: 413 | C15: 4de8d0_53_942ef8 | F15: DummyIBAN | G15: nikaelevator@gmail.com | H15: 2.1.1.6. (-) ლიფტების მონტაჟის დამხმარე მასალები | I15: Budget Dummy (ს.კ. ICE002065) - შპს | J15: Nami | 1.1.1. | ნამი 2024 | 66,150.00 USD | 16.04.2025 | L15: FALSE | N15: 708f82ba-b595-4092-9128-e4202256bd96 | O15: 45763.699 | P15: nikaelevator@gmail.com
A16: 46033.5 | B16: 647 | C16: 06940e_84_a4d6f3 | F16: GE20BG0000000129248100 | G16: nikaelevator@gmail.com | H16: 2.1.1.9. (-) ლიფტების მონტაჟის ბონუსები | I16: ნიკოლოზ ოთარაშვილი (ს.კ. 01026015799) - ფიზ. პირი | J16: Nami | 1.1.1. | ნამი 2024 | 66,150.00 USD | 16.04.2025 | L16: TRUE | N16: 7204c4cc-8e50-4a12-8898-664aa4fc69b6 | O16: 45763.699 | P16: nikaelevator@gmail.com
A17: 46023.5 | B17: 100 | C17: 3fd2b0_15_b1bf7e | E17: ბონუსი | F17: GE29BG0000000450982000 | G17: gio.nikabadze@gmail.com | H17: 3.2.1. (-) ოფისის იჯარის ხარჯი | I17: გიორგი ბახტაძე (ს.კ. 01024067298) - ფიზ. პირი | J17: Batumi Office Rent MEPPERS | 1.3.2. | მეპერსი | 2,700.00 USD | 15.08.2024 | L17: TRUE | N17: 60ee7912-968b-4aa9-b27d-a522eb3beeac | O17: 45671.698 | P17: gio.nikabadze@gmail.com
A18: 46023.5 | B18: 170 | C18: 5b57b2_7d_b1d45c | E18: ბონუსი | F18: GE29BG0000000450982000 | G18: gio.nikabadze@gmail.com | H18: 3.2.1. (-) ოფისის იჯარის ხარჯი | I18: გიორგი ბახტაძე (ს.კ. 01024067298) - ფიზ. პირი | J18: Batumi Office Rent CASA | 1.3.2. | კაზა დი ბათუმი | 500.00 USD | 15.08.2024 | L18: TRUE | N18: 055d090b-f632-4907-8fe8-fd402520c372 | O18: 45671.698 | P18: gio.nikabadze@gmail.com
A19: 46023.5 | B19: 100 | C19: 86f954_6b_816c74 | E19: ბონუსი | F19: GE22BG0000000343713900 | G19: gio.nikabadze@gmail.com | H19: 3.2.1. (-) ოფისის იჯარის ხარჯი | I19: პაატა დვალიშვილი (ს.კ. 01001011731) - ფიზ. პირი | J19: Batumi Office Rent MEPPERS | 1.3.2. | მეპერსი | 2,700.00 USD | 15.08.2024 | L19: TRUE | N19: d745d1c5-2d8b-4b7f-ba0d-33a3a918e7fe | O19: 45671.698 | P19: gio.nikabadze@gmail.com
A20: 46023.5 | B20: 170 | C20: 01c4d3_05_a5dce3 | E20: ბონუსი | F20: GE22BG0000000343713900 | G20: gio.nikabadze@gmail.com | H20: 3.2.1. (-) ოფისის იჯარის ხარჯი | I20: პაატა დვალიშვილი (ს.კ. 01001011731) - ფიზ. პირი | J20: Batumi Office Rent CASA | 1.3.2. | კაზა დი ბათუმი | 500.00 USD | 15.08.2024 | L20: TRUE | N20: 25b83317-c049-4640-8a8c-1baa7fccf63e | O20: 45671.698 | P20: gio.nikabadze@gmail.com
A21: 46023.5 | B21: 480 | C21: e3b011_7d_9b3279 | E21: ბონუსი | F21: GE29BG0000000450982000 | G21: gio.nikabadze@gmail.com | H21: 3.2.1. (-) ოფისის იჯარის ხარჯი | I21: გიორგი ბახტაძე (ს.კ. 01024067298) - ფიზ. პირი | L21: TRUE | N21: b5a82b12-9f72-4ea9-845b-1705bb6f3de6 | O21: 45671.698 | P21: gio.nikabadze@gmail.com
A22: 46023.5 | B22: 480 | C22: e05daf_4b_b0621d | E22: ბონუსი | F22: GE22BG0000000343713900 | G22: gio.nikabadze@gmail.com | H22: 3.2.1. (-) ოფისის იჯარის ხარჯი | I22: პაატა დვალიშვილი (ს.კ. 01001011731) - ფიზ. პირი | L22: TRUE | N22: 7f075687-e2a1-4b06-80b1-5f7cbd3a693c | O22: 45671.698 | P22: gio.nikabadze@gmail.com
A23: 46018.5 | B23: 1875 | C23: ba9b1d_ea_9e8480 | F23: DummyIBAN | G23: nikaelevator@gmail.com | H23: 2.1.1.3. (-) ლიფტების მონტაჟის ღირებულება | I23: Budget Dummy (ს.კ. ICE002065) - შპს | J23: Nami | 1.1.1. | ნამი 2024 | 66,150.00 USD | 16.04.2025 | L23: TRUE | N23: 844c0d67-92c7-4366-8db4-6ee2b261927f | O23: 45763.699 | P23: nikaelevator@gmail.com
A24: 46018.5 | B24: 413 | C24: 8b3401_e6_8e103b | F24: DummyIBAN | G24: nikaelevator@gmail.com | H24: 2.1.1.6. (-) ლიფტების მონტაჟის დამხმარე მასალები | I24: Budget Dummy (ს.კ. ICE002065) - შპს | J24: Nami | 1.1.1. | ნამი 2024 | 66,150.00 USD | 16.04.2025 | L24: FALSE | N24: 3003b8f2-3452-4ea0-b10c-8589e1a72d67 | O24: 45763.699 | P24: nikaelevator@gmail.com
A25: 46017.5 | B25: 11753 | C25: 05ad6a_4e_a08415 | F25: 2 | G25: dito.sichinava@gmail.com | H25: 1.1.1.5. (+) ლიფტების ჩაბარება | I25: გრანდე ჯგუფი (ს.კ. 404557127) - შპს | J25: Grande Krtsanisi D & E BlocK | 1.1.1. | გრანდე ჯგუფი | 235,060.00 USD | 13.05.2025 | L25: FALSE | N25: 725a2223-5790-4682-88db-8c436cc9f6a7 | O25: 45792.717 | P25: dito.sichinava@gmail.com
A26: 46017.5 | B26: 8650 | C26: bbc0d6_2b_9e0231 | F26: 2 | G26: dito.sichinava@gmail.com | H26: 2.1.1.4. (-) ლიფტების მონტაჟის დამხმარე შრომა | I26: Budget Dummy (ს.კ. ICE002065) - შპს | J26: Grande Krtsanisi D & E BlocK | 1.1.1. | გრანდე ჯგუფი | 235,060.00 USD | 13.05.2025 | L26: TRUE | N26: eaedf8ee-3318-4e4e-a086-490ee8a2e5ef | O26: 45792.717 | P26: dito.sichinava@gmail.com
A27: 46017.5 | B27: 1865 | C27: b851ba_6e_93ab84 | F27: 2 | G27: dito.sichinava@gmail.com | H27: 2.1.1.8. (-) ლიფტების მონტაჟის გაუთვალისწინებელი ხარჯი | I27: Budget Dummy (ს.კ. ICE002065) - შპს | J27: Grande Krtsanisi D & E BlocK | 1.1.1. | გრანდე ჯგუფი | 235,060.00 USD | 13.05.2025 | L27: FALSE | N27: 0d3c6c5f-b41e-46e6-8a8f-9d6b99e7aa93 | O27: 45792.717 | P27: dito.sichinava@gmail.com
A28: 46017.5 | B28: 862 | C28: f82938_9e_8df609 | F28: 2 | G28: dito.sichinava@gmail.com | H28: 2.1.1.9. (-) ლიფტების მონტაჟის ბონუსები | I28: Budget Dummy (ს.კ. ICE002065) - შპს | J28: Grande Krtsanisi D & E BlocK | 1.1.1. | გრანდე ჯგუფი | 235,060.00 USD | 13.05.2025 | L28: FALSE | N28: 8341843c-2e26-42a2-a8b1-7dbc5c8e51eb | O28: 45792.717 | P28: dito.sichinava@gmail.com
A29: 46000.5 | B29: 10060 | C29: 92165f_b2_83d248 | F29: GE21TB1000000036500001 | G29: dito.sichinava@gmail.com | H29: 1.1.1.5. (+) ლიფტების ჩაბარება | I29: ანაგი (ს.კ. 245416401) - შპს | J29: Social Houses Batumi | 1.1.1. | ანაგი | 201,200.00 USD | 28.02.2025 | L29: FALSE | N29: 5f09288d-0927-4cf7-a634-1f47e60c1544 | O29: 45743.605 | P29: t.tsintsadze2006@gmail.com
A30: 46000.5 | B30: 11040 | C30: e963d7_29_a0891d | F30: DummyIBAN | G30: dito.sichinava@gmail.com | H30: 2.1.1.3. (-) ლიფტების მონტაჟის ღირებულება | I30: Budget Dummy (ს.კ. ICE002065) - შპს | J30: Social Houses Batumi | 1.1.1. | ანაგი | 201,200.00 USD | 28.02.2025 | L30: TRUE | N30: 024ba79c-b4d1-4289-b0f1-39a1eb8ec37a | O30: 45743.605 | P30: t.tsintsadze2006@gmail.com
A31: 46000.5 | B31: 1382.6667 | C31: c8e43c_4c_a2d15a | F31: DummyIBAN | G31: dito.sichinava@gmail.com | H31: 2.1.1.4. (-) ლიფტების მონტაჟის დამხმარე შრომა | I31: Budget Dummy (ს.კ. ICE002065) - შპს | J31: Social Houses Batumi | 1.1.1. | ანაგი | 201,200.00 USD | 28.02.2025 | L31: FALSE | N31: 0671d69e-97e6-400b-8a6c-91179de336ce | O31: 45743.605 | P31: t.tsintsadze2006@gmail.com
A32: 46000.5 | B32: 2163 | C32: 2327e6_2f_bd5852 | F32: DummyIBAN | G32: dito.sichinava@gmail.com | H32: 2.1.1.9. (-) ლიფტების მონტაჟის ბონუსები | I32: Budget Dummy (ს.კ. ICE002065) - შპს | J32: Social Houses Batumi | 1.1.1. | ანაგი | 201,200.00 USD | 28.02.2025 | L32: FALSE | N32: 9acb8fd3-518e-4467-9c6b-395c77c12512 | O32: 45743.605 | P32: t.tsintsadze2006@gmail.com
A33: 46000.5 | B33: 900 | C33: 77589a_ee_95d789 | F33: GE26TB7457645064300069 | G33: dito.sichinava@gmail.com | H33: 2.1.1.11. (-) ლიფტების პროექტის მომსახურების ბონუსები | I33: თეა ურიდია (ს.კ. 62001030230) - ფიზ. პირი | J33: Social Houses Batumi | 1.1.1. | ანაგი | 201,200.00 USD | 28.02.2025 | L33: TRUE | N33: e2a7c21b-a255-4bf8-92c5-42e8e3f60faa | O33: 45743.605 | P33: t.tsintsadze2006@gmail.com
A34: 45992.5 | B34: 100 | C34: 3fd2b0_15_b1bf7e | E34: ბონუსი | F34: GE29BG0000000450982000 | G34: gio.nikabadze@gmail.com | H34: 3.2.1. (-) ოფისის იჯარის ხარჯი | I34: გიორგი ბახტაძე (ს.კ. 01024067298) - ფიზ. პირი | J34: Batumi Office Rent MEPPERS | 1.3.2. | მეპერსი | 300.00 USD | 15.08.2024 | L34: TRUE | N34: 733f616d-1456-4815-a7d4-7c16f93c013a | O34: 45671.698 | P34: gio.nikabadze@gmail.com
A35: 45992.5 | B35: 170 | C35: 5b57b2_7d_b1d45c | E35: ბონუსი | F35: GE29BG0000000450982000 | G35: gio.nikabadze@gmail.com | H35: 3.2.1. (-) ოფისის იჯარის ხარჯი | I35: გიორგი ბახტაძე (ს.კ. 01024067298) - ფიზ. პირი | J35: Batumi Office Rent CASA | 1.3.2. | კაზა დი ბათუმი | 500.00 USD | 15.08.2024 | L35: TRUE | N35: 6e42a7cc-6dbd-4c63-9d71-17088dbdc1d7 | O35: 45671.698 | P35: gio.nikabadze@gmail.com
A36: 45992.5 | B36: 100 | C36: 86f954_6b_816c74 | E36: ბონუსი | F36: GE22BG0000000343713900 | G36: gio.nikabadze@gmail.com | H36: 3.2.1. (-) ოფისის იჯარის ხარჯი | I36: პაატა დვალიშვილი (ს.კ. 01001011731) - ფიზ. პირი | J36: Batumi Office Rent MEPPERS | 1.3.2. | მეპერსი | 300.00 USD | 15.08.2024 | L36: TRUE | N36: 8612cafa-9488-4f3f-a112-47db131b3577 | O36: 45671.698 | P36: gio.nikabadze@gmail.com
A37: 45992.5 | B37: 170 | C37: 01c4d3_05_a5dce3 | E37: ბონუსი | F37: GE22BG0000000343713900 | G37: gio.nikabadze@gmail.com | H37: 3.2.1. (-) ოფისის იჯარის ხარჯი | I37: პაატა დვალიშვილი (ს.კ. 01001011731) - ფიზ. პირი | J37: Batumi Office Rent CASA | 1.3.2. | კაზა დი ბათუმი | 500.00 USD | 15.08.2024 | L37: TRUE | N37: b3851181-d5ab-4433-af33-3b37e0934b72 | O37: 45671.698 | P37: gio.nikabadze@gmail.com
A38: 45992.5 | B38: 480 | C38: e3b011_7d_9b3279 | E38: ბონუსი | F38: GE29BG0000000450982000 | G38: gio.nikabadze@gmail.com | H38: 3.2.1. (-) ოფისის იჯარის ხარჯი | I38: გიორგი ბახტაძე (ს.კ. 01024067298) - ფიზ. პირი | L38: TRUE | N38: c0497842-1d5e-4a4a-bc5c-5c6723856a26 | O38: 45671.698 | P38: gio.nikabadze@gmail.com
A39: 45992.5 | B39: 480 | C39: e05daf_4b_b0621d | E39: ბონუსი | F39: GE22BG0000000343713900 | G39: gio.nikabadze@gmail.com | H39: 3.2.1. (-) ოფისის იჯარის ხარჯი | I39: პაატა დვალიშვილი (ს.კ. 01001011731) - ფიზ. პირი | L39: TRUE | N39: 59d2752a-ac26-4a2e-ae05-1ae2194bb41f | O39: 45671.698 | P39: gio.nikabadze@gmail.com
A40: 45991.5 | B40: 1334 | C40: 35a808_50_90b5ae | F40: 111 | G40: dito.sichinava@gmail.com | H40: 1.1.1.5. (+) ლიფტების ჩაბარება | I40: საკენი ბიოგრაფი (ს.კ. 404651015) - შპს | J40: SaKeni | 1.1.1. | საკენი ბიოგრაფი | 26,680.00 USD | 21.05.2025 | L40: FALSE | N40: 9280da5b-03dd-4ff6-8a4b-d4f456ceccff | O40: 45807.582 | P40: dito.sichinava@gmail.com
...

Sheet Sheet1
A1: paymentId | B1: effectiveDate | C1: accrual | D1: order | E1: comment | F1: recordUuid | G1: userEmail
A2: f3ce6e_a3_beadc9 | B2: 46142 | D2: 25000 | F2: 9b744368-f75c-456d-9a8e-9bdf1ba21169 | G2: nikaelevator@gmail.com | H2: {=MATCH(A2&B2,Sheet2!$A$2:$A$6970&Sheet2!$B$2:$B$6970,0)} -> 5509 | I2: {=ISNUMBER(B2:B8118)} -> TRUE
A3: 5007c8_f0_b26d52 | B3: 46142 | D3: 962 | F3: 3447cfc3-e66b-443c-b7f2-82e9f0f949dd | G3: nikaelevator@gmail.com | H3: {=MATCH(A3&B3,Sheet2!$A$2:$A$6970&Sheet2!$B$2:$B$6970,0)} -> 5518 | I3: TRUE
A4: b83db5_84_b38688 | B4: 46127 | D4: 25000 | F4: d97adbef-875b-4fb1-8e16-522e9cda263a | G4: nikaelevator@gmail.com | H4: {=MATCH(A4&B4,Sheet2!$A$2:$A$6970&Sheet2!$B$2:$B$6970,0)} -> 5508 | I4: TRUE
A5: fc79e7_85_8e7110 | B5: 46127 | D5: 21200 | F5: 81759988-8d22-4a12-ad6d-94d4049106ab | G5: nikaelevator@gmail.com | H5: {=MATCH(A5&B5,Sheet2!$A$2:$A$6970&Sheet2!$B$2:$B$6970,0)} -> 5514 | I5: TRUE
A6: a6622d_06_a1a791 | B6: 46127 | D6: 1590 | F6: 33461393-89c8-4877-9702-0ffa90130fb1 | G6: nikaelevator@gmail.com | H6: {=MATCH(A6&B6,Sheet2!$A$2:$A$6970&Sheet2!$B$2:$B$6970,0)} -> 5517 | I6: TRUE
A7: b9aaa8_9e_9285dc | B7: 46097 | D7: 22000 | F7: b40bae34-6cd0-4dfb-bb52-929411b0f0da | G7: nikaelevator@gmail.com | H7: {=MATCH(A7&B7,Sheet2!$A$2:$A$6970&Sheet2!$B$2:$B$6970,0)} -> 5513 | I7: TRUE
A8: ba3047_8b_9b6889 | B8: 46097 | D8: 1600 | F8: aa2fe372-6fa5-416f-8e39-71b791155e41 | G8: nikaelevator@gmail.com | H8: {=MATCH(A8&B8,Sheet2!$A$2:$A$6970&Sheet2!$B$2:$B$6970,0)} -> 5516 | I8: TRUE
A9: 777dd5_69_ba96e1 | B9: 46067 | D9: 22000 | F9: cd17e642-3548-46e4-a2c7-b71991f829eb | G9: nikaelevator@gmail.com | H9: {=MATCH(A9&B9,Sheet2!$A$2:$A$6970&Sheet2!$B$2:$B$6970,0)} -> 5512 | I9: TRUE
A10: 67707d_5a_be6e2a | B10: 46067 | D10: 1600 | F10: 751c23df-ddf7-4035-bfc5-7de5a0378a58 | G10: nikaelevator@gmail.com | H10: {=MATCH(A10&B10,Sheet2!$A$2:$A$6970&Sheet2!$B$2:$B$6970,0)} -> 5515 | I10: TRUE
A11: a3a1a2_f5_be4ae3 | B11: 46037 | D11: 222000 | F11: 0cf5880f-c4ef-447d-9952-3d8b37283c52 | G11: nikaelevator@gmail.com | H11: {=MATCH(A11&B11,Sheet2!$A$2:$A$6970&Sheet2!$B$2:$B$6970,0)} -> 5507 | I11: TRUE
A12: 3197b7_5d_9c197e | B12: 46037 | D12: 36800 | F12: aea3a925-c419-445a-be02-29db9c84a7a3 | G12: nikaelevator@gmail.com | H12: {=MATCH(A12&B12,Sheet2!$A$2:$A$6970&Sheet2!$B$2:$B$6970,0)} -> 5511 | I12: TRUE
A13: 5eecbc_3a_9cc4c3 | B13: 46033 | D13: 6615 | F13: b49bc77e-fcce-4d9b-81f5-941bb5fea34f | G13: nikaelevator@gmail.com | H13: {=MATCH(A13&B13,Sheet2!$A$2:$A$6970&Sheet2!$B$2:$B$6970,0)} -> 5628 | I13: TRUE
A14: 1e93d0_c4_a2b384 | B14: 46033 | D14: 1875 | F14: 1b8c55a4-acd0-4b17-97da-9bdd1b2d7110 | G14: nikaelevator@gmail.com | H14: {=MATCH(A14&B14,Sheet2!$A$2:$A$6970&Sheet2!$B$2:$B$6970,0)} -> 5634 | I14: TRUE
... A72: 1b448f_e0_818416 | B72: 45962 | D72: 208000 | F72: eb51e6b6-12bb-4058-9815-d2b85ee42aba | G72: nikaelevator@gmail.com | H72: {=MATCH(A72&B72,Sheet2!$A$2:$A$6970&Sheet2!$B$2:$B$6970,0)} -> 5510 | I72: TRUE
A73: 03f387_32_83f33d | B73: 45960 | D73: 630 | E73: მხოლოდ 630$ ჩაერიცხა კონცელიძეს | F73: f4f76729-01ad-4960-9d94-7a9fe1023882 | G73: nikaelevator@gmail.com | H73: {=MATCH(A73&B73,Sheet2!$A$2:$A$6970&Sheet2!$B$2:$B$6970,0)} -> #N/A | I73: TRUE
A74: dac879_b2_bcbd7f | B74: 45958 | D74: 13230 | F74: cd22846b-6510-4c47-b665-218f961ac16c | G74: nikaelevator@gmail.com | H74: {=MATCH(A74&B74,Sheet2!$A$2:$A$6970&Sheet2!$B$2:$B$6970,0)} -> 5627 | I74: TRUE
A75: 24f41d_2a_a9cff2 | B75: 45958 | D75: 12450 | F75: f639993f-dd0b-484e-b913-7191a0a9ecf2 | G75: nikaelevator@gmail.com | H75: {=MATCH(A75&B75,Sheet2!$A$2:$A$6970&Sheet2!$B$2:$B$6970,0)} -> 5631 | I75: TRUE
A76: 52607e_3d_b82859 | B76: 45958 | D76: 9402 | F76: 265bd52d-cfaa-4990-839a-ff5187372d34 | G76: dito.sichinava@gmail.com | H76: {=MATCH(A76&B76,Sheet2!$A$2:$A$6970&Sheet2!$B$2:$B$6970,0)} -> 5923 | I76: TRUE
A77: c25732_51_b891b7 | B77: 45958 | D77: 4100 | F77: da8cf36e-10b6-400a-a4a3-2ca6f5f76e10 | G77: dito.sichinava@gmail.com | H77: {=MATCH(A77&B77,Sheet2!$A$2:$A$6970&Sheet2!$B$2:$B$6970,0)} -> 5928 | I77: TRUE
A78: eb7c48_51_ac2e16 | B78: 45958 | D78: 654 | F78: 318f5db2-0085-4334-b8c3-21928a0cf6b5 | G78: dito.sichinava@gmail.com | H78: {=MATCH(A78&B78,Sheet2!$A$2:$A$6970&Sheet2!$B$2:$B$6970,0)} -> 5930 | I78: TRUE
A79: 1f23e0_cf_a2d215 | B79: 45957 | D79: 35259 | F79: f9bd9584-52de-460b-a144-755c3d17074a | G79: dito.sichinava@gmail.com | H79: {=MATCH(A79&B79,Sheet2!$A$2:$A$6970&Sheet2!$B$2:$B$6970,0)} -> 5823 | I79: TRUE
A80: a3bbc5_4f_9b77c7 | B80: 45957 | D80: 15400 | F80: 2de528df-3de8-407c-a838-b62bbb777ab0 | G80: dito.sichinava@gmail.com | H80: {=MATCH(A80&B80,Sheet2!$A$2:$A$6970&Sheet2!$B$2:$B$6970,0)} -> 5827 | I80: TRUE
A81: b1bfab_2c_996082 | B81: 45955 | D81: 10060 | F81: 4c09dd8d-789d-404c-a3d8-ce3963add26e | G81: t.tsintsadze2006@gmail.com | H81: {=MATCH(A81&B81,Sheet2!$A$2:$A$6970&Sheet2!$B$2:$B$6970,0)} -> 5488 | I81: TRUE
A82: e7a388_9f_91d054 | B82: 45954 | D82: 9000 | F82: a24ba360-bc30-47c5-bbd9-4a1b27ba93fa | G82: nikaelevator@gmail.com | H82: {=MATCH(A82&B82,Sheet2!$A$2:$A$6970&Sheet2!$B$2:$B$6970,0)} -> 5295 | I82: TRUE
A83: 993716_ac_9159ba | B83: 45954 | D83: 1138.6667 | F83: 960a2230-2af8-4f87-a4e9-091a27a6ff0a | G83: nikaelevator@gmail.com | H83: {=MATCH(A83&B83,Sheet2!$A$2:$A$6970&Sheet2!$B$2:$B$6970,0)} -> 5298 | I83: TRUE
A84: 50f0f7_ac_9616f8 | B84: 45942 | D84: 1334 | F84: 0667bd0c-3f69-4bd0-b236-590e11ebbbef | G84: dito.sichinava@gmail.com | H84: {=MATCH(A84&B84,Sheet2!$A$2:$A$6970&Sheet2!$B$2:$B$6970,0)} -> 5910 | I84: TRUE
A85: cdf6f4_f5_964395 | B85: 45941 | D85: 2350 | F85: 883dfffb-df3e-4af4-8c3f-ab822f4fc61b | G85: nikaelevator@gmail.com | H85: {=MATCH(A85&B85,Sheet2!$A$2:$A$6970&Sheet2!$B$2:$B$6970,0)} -> 5388 | I85: TRUE
... A105: 93582a_91_bd23aa | B105: 45924 | D105: 1138.6667 | F105: 39a53714-d031-4b46-9cdd-da1ac8b0e20f | G105: nikaelevator@gmail.com | H105: {=MATCH(A105&B105,Sheet2!$A$2:$A$6970&Sheet2!$B$2:$B$6970,0)} -> 5297 | I105: TRUE
A106: f0e746_dc_8f772e | B106: 45915 | D106: 953.8 | E106: მანქანა #4 | F106: 225b0d63-2fe0-44cf-918b-020ec918bad0 | G106: gio.nikabadze@gmail.com | H106: {=MATCH(A106&B106,Sheet2!$A$2:$A$6970&Sheet2!$B$2:$B$6970,0)} -> 4012 | I106: TRUE
A107: 3204ba_8e_a03b4d | B107: 45912 | D107: 9200 | F107: 9c7856e3-2178-476b-b295-6506e84d07cd | G107: nikaelevator@gmail.com | H107: {=MATCH(A107&B107,Sheet2!$A$2:$A$6970&Sheet2!$B$2:$B$6970,0)} -> 5306 | I107: TRUE
A108: 9d9b5e_80_96bbe4 | B108: 45912 | D108: 3500 | F108: 8a367363-587f-4c65-ad34-221cd1e6a456 | G108: nikaelevator@gmail.com | H108: {=MATCH(A108&B108,Sheet2!$A$2:$A$6970&Sheet2!$B$2:$B$6970,0)} -> 5311 | I108: TRUE
A109: cd2134_89_9c02ef | B109: 45912 | D109: 500 | F109: 80fc9dbc-b3e2-4c9c-ab44-76161c483d36 | G109: nikaelevator@gmail.com | H109: {=MATCH(A109&B109,Sheet2!$A$2:$A$6970&Sheet2!$B$2:$B$6970,0)} -> 5313 | I109: TRUE
A110: 88a1c5_cf_849d34 | B110: 45912 | D110: 829 | F110: eb9743d0-95dc-4773-9e4c-17e8dff0dfd3 | G110: nikaelevator@gmail.com | H110: {=MATCH(A110&B110,Sheet2!$A$2:$A$6970&Sheet2!$B$2:$B$6970,0)} -> 5315 | I110: TRUE
A111: 8993e6_9f_b16e46 | B111: 45912 | D111: 431 | F111: a255e0e7-0a9a-4ecb-9649-db07f6412be1 | G111: nikaelevator@gmail.com | H111: {=MATCH(A111&B111,Sheet2!$A$2:$A$6970&Sheet2!$B$2:$B$6970,0)} -> 5316 | I111: TRUE
A112: d35a7d_48_a5b35c | B112: 45910 | D112: 50300 | F112: ec9fb7ba-a491-4850-bc9e-6ab6b8ab5ad6 | G112: t.tsintsadze2006@gmail.com | H112: {=MATCH(A112&B112,Sheet2!$A$2:$A$6970&Sheet2!$B$2:$B$6970,0)} -> 5487 | I112: TRUE
A113: 53fb3e_b8_85c957 | B113: 45910 | D113: 18850 | F113: b0b44bdb-8f32-4105-8968-1d30d28becd5 | G113: t.tsintsadze2006@gmail.com | H113: {=MATCH(A113&B113,Sheet2!$A$2:$A$6970&Sheet2!$B$2:$B$6970,0)} -> 5491 | I113: TRUE
A114: 996ba1_b6_ac0529 | B114: 45910 | D114: 1667 | F114: 7e0c7e94-8425-4508-874d-41e6843dc5b4 | G114: t.tsintsadze2006@gmail.com | H114: {=MATCH(A114&B114,Sheet2!$A$2:$A$6970&Sheet2!$B$2:$B$6970,0)} -> 5498 | I114: TRUE
A115: 3fd2b0_15_b1bf7e | B115: 45901 | D115: 100 | F115: 739caa67-d422-47b0-8e22-09a4e31ef129 | G115: gio.nikabadze@gmail.com | H115: {=MATCH(A115&B115,Sheet2!$A$2:$A$6970&Sheet2!$B$2:$B$6970,0)} -> 4550 | I115: TRUE
A116: 5b57b2_7d_b1d45c | B116: 45901 | D116: 170 | F116: bcf8616a-d921-4989-8b5c-de9d4874647b | G116: gio.nikabadze@gmail.com | H116: {=MATCH(A116&B116,Sheet2!$A$2:$A$6970&Sheet2!$B$2:$B$6970,0)} -> 4551 | I116: TRUE
...

Sheet paymentsledger
A1: paymentId | B1: effectiveDate | C1: accrual | D1: order | E1: comment | F1: recordUuid | G1: userEmail
A2: f0e746_dc_8f772e | B2: 46293 | C2: 1071.3 | D2: 1071.3 | E2: დასტერი | F2: b562e038-6e5e-4e12-ba53-56a0875cba04 | G2: dito.sichinava@gmail.com
A3: 78a10b_38_a4410f | B3: 46280 | C3: 9885 | D3: 9885 | F3: e729c2d6-7d02-4fdf-b5e4-233dc24e127d | G3: dito.sichinava@gmail.com
A4: 166a1a_0c_a96f66 | B4: 46280 | C4: 24020 | D4: 24020 | F4: c8ce5212-fedb-429e-b493-1d5b2f8587aa | G4: dito.sichinava@gmail.com
A5: cd6bf6_9b_b6ad1e | B5: 46280 | C5: 4310 | D5: 4310 | E5: აქ შედის ზედამხედველობის 880$ | F5: f578b9d3-7347-46f5-b377-82bd2fc01058 | G5: dito.sichinava@gmail.com
A6: 065489_e6_8ab012 | B6: 46280 | C6: 740.8 | D6: 740.8 | F6: b2a8e04b-38d9-4590-809b-af63ebb93708 | G6: dito.sichinava@gmail.com
A7: f0e746_dc_8f772e | B7: 46262 | C7: 1071.3 | D7: 1071.3 | E7: დასტერი | F7: 773faea1-520b-4fa0-a735-df528e5e52f8 | G7: dito.sichinava@gmail.com
A8: 66b7b1_ea_97fc6e | B8: 46250 | C8: 22240 | D8: 22240 | F8: 7b1e6fa5-6fbb-4dc4-a523-a6577771a511 | G8: dito.sichinava@gmail.com
A9: f0e746_dc_8f772e | B9: 46231 | C9: 1071.3 | D9: 1071.3 | E9: დასტერი | F9: 46752a10-a86d-414b-8bf0-b1358c08b38f | G9: dito.sichinava@gmail.com
A10: f0e746_dc_8f772e | B10: 46201 | C10: 1071.3 | D10: 1071.3 | E10: დასტერი | F10: f3b17f4a-9d08-4248-a200-05d9ec505477 | G10: dito.sichinava@gmail.com
A11: 370528_7e_83c640 | B11: 46190 | C11: 34597 | D11: 34597 | F11: c879edec-4c1e-465f-83b0-ad5c370f55f3 | G11: dito.sichinava@gmail.com
A12: f0f5f4_38_81dab6 | B12: 46190 | C12: 10600 | D12: 10600 | F12: c2a05e30-7a1f-4e68-b9a4-568cd563ed2d | G12: dito.sichinava@gmail.com
A13: f0e746_dc_8f772e | B13: 46170 | C13: 1071.3 | D13: 1071.3 | E13: დასტერი | F13: 81794777-b62e-4bc4-9c47-fde1504ab8eb | G13: dito.sichinava@gmail.com
A14: 71a80d_2e_b7eed3 | B14: 46143 | C14: 1500 | D14: 1500 | E14: 5_2026 | F14: a4f12b94-a935-4376-9bf9-d22b086cd0bc | G14: dito.sichinava@gmail.com
A15: f3ce6e_a3_beadc9 | B15: 46142 | C15: 25000 | D15: 25000 | F15: 943203ba-4295-496a-81aa-c3887e77d088 | G15: nikaelevator@gmail.com
A16: 5007c8_f0_b26d52 | B16: 46142 | C16: 962 | D16: 962 | F16: 007057d2-bfc3-4479-b2b5-42505855359b | G16: dito.sichinava@gmail.com
A17: 01b09d_06_b32e00 | B17: 46142 | C17: 7700 | D17: 7700 | F17: 90285ff7-d6d3-42e3-beca-c8f17ce12af7 | G17: dito.sichinava@gmail.com
A18: 8d5919_80_8dd7af | B18: 46142 | C18: 9400 | D18: 9400 | F18: a1cded52-13d2-4d79-81bb-f082d7dcb041 | G18: dito.sichinava@gmail.com
A19: 98df19_46_bce836 | B19: 46142 | C19: 925 | D19: 925 | F19: 6d427b6f-891e-493a-bb43-8c4626ba9b2e | G19: dito.sichinava@gmail.com
A20: fafa8e_c1_96f3be | B20: 46142 | C20: 431.03448 | D20: 431.03448 | F20: f8e76eb0-097f-414c-8d58-867d424c6add | G20: dito.sichinava@gmail.com
A21: f0e746_dc_8f772e | B21: 46140 | C21: 1071.3 | D21: 1071.3 | E21: დასტერი | F21: 8aa774db-dc8f-49c5-83cd-b4bc7ede146a | G21: dito.sichinava@gmail.com
A22: 3c2808_03_b9dce5 | B22: 46137 | C22: 7025 | D22: 7025 | F22: 6e905bcc-b405-459b-829c-3648081a80b9 | G22: dito.sichinava@gmail.com
A23: e7ddc9_e9_af1bef | B23: 46130 | C23: 7750 | D23: 7750 | F23: 18b7d9c0-7fbd-4a00-aa8d-7caab85fb359 | G23: dito.sichinava@gmail.com
A24: 3868ab_e7_aafae9 | B24: 46130 | C24: 9500 | D24: 9500 | F24: 7b50e190-ddae-4c59-b57e-3c9e6527f170 | G24: dito.sichinava@gmail.com
A25: 29a975_c6_a55b6e | B25: 46130 | C25: 481 | D25: 481 | F25: 169af46b-6fa3-4df0-a443-baa7f6041441 | G25: dito.sichinava@gmail.com
A26: 89f289_69_ad84ec | B26: 46128 | C26: 3040.5 | D26: 3040.5 | F26: c5a9a601-555f-492a-8c29-21f236507f54 | G26: dito.sichinava@gmail.com
A27: b83db5_84_b38688 | B27: 46127 | C27: 25000 | D27: 25000 | F27: c667ecb5-ceb0-46b1-b32b-155f955d9dc4 | G27: nikaelevator@gmail.com
A28: fc79e7_85_8e7110 | B28: 46127 | C28: 21200 | D28: 21200 | F28: abd9ff61-5642-4a1f-a7c4-11fd0a740fcd | G28: dito.sichinava@gmail.com
A29: a6622d_06_a1a791 | B29: 46127 | C29: 1590 | D29: 1590 | F29: 46896653-214f-4bb0-a4e1-c58b3eb841ff | G29: dito.sichinava@gmail.com
A30: 71a80d_2e_b7eed3 | B30: 46113 | C30: 1500 | D30: 1500 | E30: 4_2026 | F30: 86c04ee2-1742-4fbd-bcf5-60f619fa03b0 | G30: dito.sichinava@gmail.com
A31: f7af4e_98_bf8f1f | B31: 46113 | C31: 3040.5 | D31: 3040.5 | F31: 62e920e5-b2a2-4a04-a989-8ac332828133 | G31: dito.sichinava@gmail.com
A32: 4aea25_96_802d92 | B32: 46113 | C32: 3500 | D32: 3500 | F32: 17d2ac8b-911c-4941-87a7-ce6542547e03 | G32: dito.sichinava@gmail.com
A33: bbbca2_71_a5e42f | B33: 46113 | C33: 934 | D33: 934 | F33: 11b74504-ca46-4cb3-bcf5-f6c3edba4c67 | G33: dito.sichinava@gmail.com
A34: 59c7f2_c9_a713a7 | B34: 46113 | C34: 240.38462 | D34: 240.38462 | F34: 3fa14c58-3baf-4dad-9548-536cd5ff70f5 | G34: dito.sichinava@gmail.com
A35: f0e746_dc_8f772e | B35: 46109 | C35: 1071.3 | D35: 1071.3 | E35: დასტერი | F35: c11bd946-e7a4-4a2a-842f-b9c3c4130f4b | G35: dito.sichinava@gmail.com
A36: b73629_18_900218 | B36: 46107 | C36: 7025 | D36: 7025 | F36: dc5886ca-09ef-42c2-a326-4235490d7172 | G36: dito.sichinava@gmail.com
A37: cb8906_e1_b19938 | B37: 46100 | C37: 15500 | D37: 15500 | F37: 0124426e-6c2c-4aad-8b11-bd6d667fe079 | G37: dito.sichinava@gmail.com
A38: 169b33_f8_a0ab74 | B38: 46100 | C38: 9500 | D38: 9500 | F38: 62eceab3-e5ab-4eab-93ae-e468c180dde9 | G38: dito.sichinava@gmail.com
A39: bc9624_b2_816c2d | B39: 46100 | C39: 1681 | D39: 1681 | F39: 635706bf-58ae-4b7d-806c-b1c6a0f69843 | G39: dito.sichinava@gmail.com
A40: 6a5647_35_816ec5 | B40: 46100 | C40: 81550 | D40: 81550 | F40: 5d995b21-5355-4fb6-b944-412956497729 | G40: dito.sichinava@gmail.com
...

Sheet Sheet2
A1: paymentId | B1: effectiveDate | C1: accrual | D1: order | E1: comment | F1: recordUuid | G1: userEmail
A2: e5165a_c0_9c34f0 | B2: 44515 | C2: 216624 | D2: =SUMIFs(Sheet1!D:D,Sheet1!A:A, A2,Sheet1!B:B, B2) -> 216624 | F2: 76aee41f-6e87-44c7-a98e-b0abe7d90a53 | G2: t.tsintsadze2006@gmail.com | I2: {=ISNUMBER(B2:B6970)} -> TRUE
A3: e2f304_19_88d27d | B3: 44515 | C3: 70548.3 | D3: =SUMIFs(Sheet1!D:D,Sheet1!A:A, A3,Sheet1!B:B, B3) -> 70548.3 | F3: 00f2db4b-9275-4d85-b961-89e741cc39a4 | G3: t.tsintsadze2006@gmail.com | I3: TRUE
A4: 48bc50_b1_9d1d98 | B4: 44561 | C4: 500800 | D4: =SUMIFs(Sheet1!D:D,Sheet1!A:A, A4,Sheet1!B:B, B4) -> 0 | F4: 8af4d6c6-772e-4c82-81b0-1caa293e86bf | G4: t.tsintsadze2006@gmail.com | I4: TRUE
A5: 2444ab_7d_93b08f | B5: 44573 | C5: 89323.6 | D5: =SUMIFs(Sheet1!D:D,Sheet1!A:A, A5,Sheet1!B:B, B5) -> 89323.6 | F5: 6084fd44-6467-4cb5-b18c-6c12faae47f0 | G5: t.tsintsadze2006@gmail.com | I5: TRUE
A6: 427177_39_b41c6c | B6: 44582 | C6: 77770 | D6: =SUMIFs(Sheet1!D:D,Sheet1!A:A, A6,Sheet1!B:B, B6) -> 77770 | F6: 49d27129-e214-4369-a39d-1e49b2151abe | G6: nikaelevator@gmail.com | I6: TRUE
A7: 1f42f3_6f_b98fac | B7: 44589 | C7: 602943.57 | D7: =SUMIFs(Sheet1!D:D,Sheet1!A:A, A7,Sheet1!B:B, B7) -> 602943.57 | F7: 83a3ef1c-1dc6-4c26-9d2f-d6fae1769037 | G7: nikaelevator@gmail.com | I7: TRUE
A8: d2c9a4_b9_88ccc8 | B8: 44589 | C8: 26000 | D8: =SUMIFs(Sheet1!D:D,Sheet1!A:A, A8,Sheet1!B:B, B8) -> 26000 | F8: 11464d5e-ced9-475d-91e4-3faa519b9a16 | G8: nikaelevator@gmail.com | I8: TRUE
A9: 87b8b7_2e_aa9e0f | B9: 44599 | C9: 240000 | D9: =SUMIFs(Sheet1!D:D,Sheet1!A:A, A9,Sheet1!B:B, B9) -> 240000 | F9: 335a728d-64b0-4a98-9b6d-b9c9c4a62c74 | G9: t.tsintsadze2006@gmail.com | I9: TRUE
A10: a965cd_b0_859d3c | B10: 44620 | C10: 270780 | D10: =SUMIFs(Sheet1!D:D,Sheet1!A:A, A10,Sheet1!B:B, B10) -> 270780 | F10: c3ab9e5a-4741-410a-b71b-d41fcf2c4ff6 | G10: t.tsintsadze2006@gmail.com | I10: TRUE
A11: 31b6a3_c9_87cf10 | B11: 44635 | C11: 178850 | D11: =SUMIFs(Sheet1!D:D,Sheet1!A:A, A11,Sheet1!B:B, B11) -> 178850 | F11: 5d53d2cd-694c-4b1e-959b-8f1643cec98d | G11: t.tsintsadze2006@gmail.com | I11: TRUE
A12: d2c9a4_b9_88ccc8 | B12: 44655 | C12: 11880 | D12: =SUMIFs(Sheet1!D:D,Sheet1!A:A, A12,Sheet1!B:B, B12) -> 11880 | F12: 393bfcf7-d427-45b5-856f-fe9dbaa86ef9 | G12: nikaelevator@gmail.com | I12: TRUE
A13: d2c9a4_b9_88ccc8 | B13: 44657 | C13: 18377.1 | D13: =SUMIFs(Sheet1!D:D,Sheet1!A:A, A13,Sheet1!B:B, B13) -> 18377.1 | F13: e45248e8-6f63-425e-b099-cbea20ef8bff | G13: nikaelevator@gmail.com | I13: TRUE
A14: ba7562_a3_a36397 | B14: 44665 | C14: 324936 | D14: =SUMIFs(Sheet1!D:D,Sheet1!A:A, A14,Sheet1!B:B, B14) -> 324936 | F14: 638c4ba5-b819-4d8e-ba73-64529d503ec9 | G14: t.tsintsadze2006@gmail.com | I14: TRUE
... A93: 0a6c18_7c_ae5d25 | B93: 44805 | C93: -520 | D93: =SUMIFs(Sheet1!D:D,Sheet1!A:A, A93,Sheet1!B:B, B93) -> 0 | F93: 6d1a0511-8abc-417a-b772-0f4064d5394b | G93: t.tsintsadze2006@gmail.com | I93: TRUE
A94: 90fd3b_4e_ba034e | B94: 44805 | C94: 2080 | D94: =SUMIFs(Sheet1!D:D,Sheet1!A:A, A94,Sheet1!B:B, B94) -> 0 | E94: ყაჭეიშვილი/ჰამიდა 50/50 | F94: aa916643-5f20-4a45-8034-d5fab9a8e99a | G94: t.tsintsadze2006@gmail.com | I94: TRUE
A95: 92b6d5_41_962daf | B95: 44805 | C95: 2080 | D95: =SUMIFs(Sheet1!D:D,Sheet1!A:A, A95,Sheet1!B:B, B95) -> 0 | E95: ყაჭეიშვილი/ჰამიდა 50/50 | F95: dcfb286a-6795-4b2c-932c-0ef83dd3428e | G95: t.tsintsadze2006@gmail.com | I95: TRUE
A96: 6fcf6b_4d_92f52d | B96: 44805 | C96: 1250 | D96: =SUMIFs(Sheet1!D:D,Sheet1!A:A, A96,Sheet1!B:B, B96) -> 0 | E96: თურქული ლიფტის ელექტრო მონტაჟი | F96: e12600a3-a8bb-43e4-9fc2-c74e920ec766 | G96: t.tsintsadze2006@gmail.com | I96: TRUE
A97: b94197_21_95579c | B97: 44805 | C97: 187884 | D97: =SUMIFs(Sheet1!D:D,Sheet1!A:A, A97,Sheet1!B:B, B97) -> 187884 | F97: 0e3cc00e-0983-45fb-8691-b11414ae4784 | G97: nikaelevator@gmail.com | I97: TRUE
A98: d9c6af_54_eadde1 | B98: 44816 | C98: 2100 | D98: =SUMIFs(Sheet1!D:D,Sheet1!A:A, A98,Sheet1!B:B, B98) -> 0 | F98: 2efb17a8-cc2c-4225-b569-e5c4537511ba | G98: t.tsintsadze2006@gmail.com | I98: TRUE
A99: 967b88_31_072e1c | B99: 44816 | C99: 2100 | D99: =SUMIFs(Sheet1!D:D,Sheet1!A:A, A99,Sheet1!B:B, B99) -> 0 | F99: cf56413b-dc5a-499c-bda3-df8c8e37e6b5 | G99: t.tsintsadze2006@gmail.com | I99: TRUE
A100: a0d21b_5c_cdaa53 | B100: 44816 | C100: 2100 | D100: =SUMIFs(Sheet1!D:D,Sheet1!A:A, A100,Sheet1!B:B, B100) -> 0 | F100: 66d2ddca-eefa-4c31-a35d-124ba30f7c4f | G100: t.tsintsadze2006@gmail.com | I100: TRUE
A101: 23a2ba_cb_c2b9a7 | B101: 44816 | C101: 900 | D101: =SUMIFs(Sheet1!D:D,Sheet1!A:A, A101,Sheet1!B:B, B101) -> 0 | F101: f1e045d1-85f1-4e36-8ab0-1bf59129799d | G101: t.tsintsadze2006@gmail.com | I101: TRUE
A102: af6073_47_fe697c | B102: 44816 | C102: 600 | D102: =SUMIFs(Sheet1!D:D,Sheet1!A:A, A102,Sheet1!B:B, B102) -> 0 | F102: 17ecfc82-eb6b-4b79-8c7c-84fe7857f73d | G102: t.tsintsadze2006@gmail.com | I102: TRUE
A103: 49e021_94_ee7ddb | B103: 44816 | C103: 1000 | D103: =SUMIFs(Sheet1!D:D,Sheet1!A:A, A103,Sheet1!B:B, B103) -> 0 | F103: a3b019e7-9680-4708-8bf7-cb961e2a41ab | G103: t.tsintsadze2006@gmail.com | I103: TRUE
A104: bbeab1_70_c49bc8 | B104: 44816 | C104: 4930 | D104: =SUMIFs(Sheet1!D:D,Sheet1!A:A, A104,Sheet1!B:B, B104) -> 0 | F104: 5ea9c7a2-9998-408d-a6d9-cd66c28fe3b3 | G104: t.tsintsadze2006@gmail.com | I104: TRUE
A105: e8c432_f9_fa073a | B105: 44816 | C105: 1000 | D105: =SUMIFs(Sheet1!D:D,Sheet1!A:A, A105,Sheet1!B:B, B105) -> 0 | F105: fbe36755-f1f5-4de9-acc0-24efe5072043 | G105: t.tsintsadze2006@gmail.com | I105: TRUE
A106: 279f4b_c4_83101e | B106: 44816 | C106: 1000 | D106: =SUMIFs(Sheet1!D:D,Sheet1!A:A, A106,Sheet1!B:B, B106) -> 0 | F106: 915224f3-42ad-447a-9218-231e5f504d4b | G106: t.tsintsadze2006@gmail.com | I106: TRUE
A107: 39a699_82_ac3ab8 | B107: 44816 | C107: 1000 | D107: =SUMIFs(Sheet1!D:D,Sheet1!A:A, A107,Sheet1!B:B, B107) -> 0 | F107: e7850617-f014-466b-8085-94457123b60c | G107: t.tsintsadze2006@gmail.com | I107: TRUE
A108: 85de02_c8_5c0681 | B108: 44816 | C108: 1000 | D108: =SUMIFs(Sheet1!D:D,Sheet1!A:A, A108,Sheet1!B:B, B108) -> 0 | F108: 50b9c526-f5b9-436f-9e4a-de433bb7f6cc | G108: t.tsintsadze2006@gmail.com | I108: TRUE
... A199: 39f40c_65_9bc762 | B199: 44900 | C199: 311154.59 | D199: =SUMIFs(Sheet1!D:D,Sheet1!A:A, A199,Sheet1!B:B, B199) -> 311154.59 | F199: 9108d409-9177-4e03-9e75-07476059a16e | G199: t.tsintsadze2006@gmail.com | I199: TRUE
A200: 82a0b7_55_844b1d | B200: 44917 | C200: 50 | D200: =SUMIFs(Sheet1!D:D,Sheet1!A:A, A200,Sheet1!B:B, B200) -> 0 | E200: ძველი არადეკლარირების გამო 96 გადახდა გვთხოვა თანხის დამატება + ამ შეკვეთის 1% = 5$ | F200: 627f4d34-57e8-4b01-8533-bab0cbbf1c7b | G200: nikaelevator@gmail.com | I200: TRUE
A201: d57716_c5_8173a3 | B201: 44917 | C201: 100 | D201: =SUMIFs(Sheet1!D:D,Sheet1!A:A, A201,Sheet1!B:B, B201) -> 0 | F201: c6df6ebd-033a-4d72-8558-06a0b60f26e5 | G201: nikaelevator@gmail.com | I201: TRUE
A202: 78faf6_af_ad4294 | B202: 44921 | C202: 800 | D202: =SUMIFs(Sheet1!D:D,Sheet1!A:A, A202,Sheet1!B:B, B202) -> 800 | F202: 62b119c3-fa2d-4fec-bb95-d2c3fe0e92db | G202: t.tsintsadze2006@gmail.com | I202: TRUE
A203: ef8238_04_8053f9 | B203: 44921 | C203: 750 | D203: =SUMIFs(Sheet1!D:D,Sheet1!A:A, A203,Sheet1!B:B, B203) -> 0 | F203: f73c8c75-7454-4aa5-b620-bef3ad3b7af1 | G203: t.tsintsadze2006@gmail.com | I203: TRUE
A204: cc5a7d_c1_88c1af | B204: 44921 | C204: 700 | D204: =SUMIFs(Sheet1!D:D,Sheet1!A:A, A204,Sheet1!B:B, B204) -> 700 | F204: 4ee064c8-65c6-49bc-8090-cd72ca6bced6 | G204: t.tsintsadze2006@gmail.com | I204: TRUE
A205: 0ac63d_8e_865110 | B205: 44921 | C205: 400 | D205: =SUMIFs(Sheet1!D:D,Sheet1!A:A, A205,Sheet1!B:B, B205) -> 400 | E205: 4 შახტა * 100₾ | F205: a83eeede-ac32-4d83-9a2d-b0ea365455a8 | G205: nikaelevator@gmail.com | I205: TRUE
A206: a5af2c_d9_bc9545 | B206: 44921 | C206: 300 | D206: =SUMIFs(Sheet1!D:D,Sheet1!A:A, A206,Sheet1!B:B, B206) -> 300 | E206: 3 შახტა * 100₾ | F206: b530eee4-0be4-44a5-b1c5-8b3fde7a02b7 | G206: nikaelevator@gmail.com | I206: TRUE
A207: 8f60a2_fa_86c127 | B207: 44921 | C207: 70 | D207: =SUMIFs(Sheet1!D:D,Sheet1!A:A, A207,Sheet1!B:B, B207) -> 70 | E207: 1 შახტა | F207: 4bfac12d-2632-4fae-a373-4391db510955 | G207: nikaelevator@gmail.com | I207: TRUE
A208: 67149c_44_8d4f7d | B208: 44927 | C208: 62628 | D208: =SUMIFs(Sheet1!D:D,Sheet1!A:A, A208,Sheet1!B:B, B208) -> 62628 | F208: ac4e6dcd-baf4-4bcf-99a9-a06e21475146 | G208: nikaelevator@gmail.com | I208: TRUE
...
